Workbook

Sheet OVERALL SUMMARY 
B2: DAYS | C2: Night driving | D2: Early start | E2: Driving Without Convoy Night | F2: Driving Without Convoy Day | G2: Exceeded idle | H2: HARSH BRAKE | I2: Over Speeding
B3: FEBRUARY MONTH 2026 | C3: =COUNTIF('NIGHT DRIVING REPORT '!L:L,C2) -> 29 | D3: =COUNTIF('NIGHT DRIVING REPORT '!L:L,D2) -> 60 | E3: =COUNTIF('NIGHT DRIVING REPORT '!L:L,E2) -> 0 | F3: 1 | G3: =SUM('IDLING VIOLATION'!H:H) -> 4292 | H3: =SUM('HARSH BRAKE VIOLATION'!H:H) -> 1535 | I3: =SUM(' OVER SPEEDING VIOLATION '!I:I) -> 943
B4: 46081 | C4: 0 | D4: 4 | E4: 0 | F4: 0 | G4: 120 | H4: 28 | I4: 22
C33: Cummulative February Violation | F33: Yesterdays Violation

Sheet FOR SHEQ
A1: RPT_DT | B1: 2026-02-28 | D1: RPT_DT | E1: 2026-02-28 | G1: RPT_DT | H1: 28.02.2026 | J1: RPT_DT | K1: 2026-02-28
A2: IDLING VOLATION | D2: HARSH BRAKE VIOLATION | G2: OVER SPEEDING VIOLATION | J2: NIGHT DRIVING REPORT
A3: Row Labels | B3: Sum of NO OF EVENTS | D3: TRUCK NO | E3: NO OF EVENTS | G3: Row Labels | H3: Sum of Count | J3: Count of Offense | K3: Column Labels
A4: T518EBY | B4: 4 | D4: T892EBW | E4: 6 | G4: T373DHG | H4: 11 | J4: Row Labels | K4: Early start | L4: Grand Total
A5: T603DTQ | B5: 3 | D5: T425DHG | E5: 5 | G5: T890EBW | H5: 1 | J5: T264EBX | K5: 1 | L5: 1
A6: T747DEB | B6: 3 | D6: T511EBY | E6: 3 | G6: T579DTQ | H6: 1 | J6: T561DYR | K6: 1 | L6: 1
A7: T581DYR | B7: 4 | D7: T915EBW | E7: 4 | G7: T365DHG | H7: 1 | J7: T579DTQ | K7: 1 | L7: 1
A8: T746DEB | B8: 3 | D8: T930EBW | E8: 3 | G8: T435DHG | H8: 1 | J8: T945EBW | K8: 1 | L8: 1
A9: T797DYR | B9: 4 | D9: T952DSX | E9: 4 | G9: T915EBW | H9: 4 | J9: Grand Total | K9: 4 | L9: 4
A10: T799DYR | B10: 3 | D10: T435DHG | E10: 3 | G10: T581DYR | H10: 1
A11: T184EBX | B11: 4 | D11: Grand Total | E11: 28 | G11: T600DTQ | H11: 1
A12: T869EBY | B12: 4 | G12: T652DTQ | H12: 1
A13: T402ECN | B13: 3 | G13: Grand Total | H13: 22
A14: T941EBW | B14: 4
A15: T405DHG | B15: 3
A16: T514EBY | B16: 3
A17: T817EBW | B17: 4
A18: T723DYR | B18: 4
A19: T689DEB | B19: 3
A20: T734EBX | B20: 3
A21: T815DDS | B21: 3
A22: T127EBX | B22: 4
A23: T413DHE | B23: 3
A24: T572DEB | B24: 3
A25: T600DTQ | B25: 3
... A38: Grand Total | B38: 120

Sheet IDLING VIOLATION
A1: SN | B1: TRUCK NO | C1: Event time | D1: RPT_DT | E1: Time received | F1: Event text | G1: Location | H1: NO OF EVENTS
A2: 1 | B2: T129EBX | C2: 46054.456 | D2: 2026-02-01 | E2: 46054.477 | F2: T129EBX => IDLING. At 01.02.2026 10:56:52 it moved with speed 0 km/h near 'T1, Njombe, Tanzania, Mbalamaziwa'. | G2: T1, Mbalamaziwa | H2: 3
A3: 2 | B3: T150EBX | C3: 46054.387 | D3: 2026-02-01 | E3: 46054.408 | F3: T150EBX => IDLING. At 01.02.2026 09:16:52 it moved with speed 0 km/h near 'Rn1, Haut-Katanga, Democratic Republic of the Congo, 26.71 km from Lubumbashi'. | G3: Rn1, 26.71 km from Lubumbashi | H3: 3
A4: 3 | B4: T166EBX | C4: 46054.452 | D4: 2026-02-01 | E4: 46054.473 | F4: T166EBX => IDLING. At 01.02.2026 10:50:23 it moved with speed 0 km/h near 'T1, Mbeya, Tanzania, Kongolo Mkola'. | G4: T1, Kongolo Mkola | H4: 5
A5: 4 | B5: T172EBX | C5: 46054.53 | D5: 2026-02-01 | E5: 46054.551 | F5: T172EBX => IDLING. At 01.02.2026 12:43:46 it moved with speed 0 km/h near 'Regional Hospital Road, Mbeya, Nzovwe, Tanzania, 2.41 km from Mbeya'. | G5: Regional Hospital Road, 2.41 km from Mbeya | H5: 3
A6: 5 | B6: T220EBX | C6: 46054.625 | D6: 2026-02-01 | E6: 46054.646 | F6: T220EBX => IDLING. At 01.02.2026 15:00:15 it moved with speed 0 km/h near 'Rn1, Haut-Katanga, Democratic Republic of the Congo, 3.69 km from Kasumbalesa'. | G6: Rn1, 3.69 km from Kasumbalesa | H6: 3
A7: 6 | B7: T227EBX | C7: 46054.389 | D7: 2026-02-01 | E7: 46054.41 | F7: T227EBX => IDLING. At 01.02.2026 09:20:24 it moved with speed 0 km/h near 'Fisenge Bypass, Ndola, Copperbelt Province, Zambia'. | G7: Ndola, Fisenge Bypass | H7: 3
A8: 7 | B8: T250EBX | C8: 46054.348 | D8: 2026-02-01 | E8: 46054.369 | F8: T250EBX => IDLING. At 01.02.2026 08:21:03 it moved with speed 0 km/h near 'T1, Mbeya, Mbozi, Tanzania, 8.00 km from Ivugula'. | G8: T1, 8.00 km from Ivugula | H8: 3
A9: 8 | B9: T263DDJ | C9: 46054.486 | D9: 2026-02-01 | E9: 46054.507 | F9: T263DDJ => IDLING. At 01.02.2026 11:39:59 it moved with speed 0 km/h near 'Iringa Road, Lundamatwe, Iringa, Tanzania'. | G9: Lundamatwe, Iringa Road | H9: 3
A10: 9 | B10: T267DDJ | C10: 46054.465 | D10: 2026-02-01 | E10: 46054.493 | F10: T267DDJ => IDLING. At 01.02.2026 11:08:55 it moved with speed 0 km/h near 'Ndola - Kitwe Dual-Carriageway, Copperbelt Province, Zambia, 33.24 km from Ndola'. | G10: Ndola - Kitwe Dual-Carriageway, 33.24 km from Ndola | H10: 7
A11: 10 | B11: T301EBX | C11: 46054.368 | D11: 2026-02-01 | E11: 46054.389 | F11: T301EBX => IDLING. At 01.02.2026 08:50:19 it moved with speed 0 km/h near 'Rn1, Haut-Katanga, Democratic Republic of the Congo, 26.96 km from Lubumbashi'. | G11: Rn1, 26.96 km from Lubumbashi | H11: 3
A12: 11 | B12: T314DDJ | C12: 46054.549 | D12: 2026-02-01 | E12: 46054.57 | F12: T314DDJ => IDLING. At 01.02.2026 13:11:12 it moved with speed 0 km/h near 'Great North Road, Central Province, Zambia, Serenje'. | G12: Great North Road, Serenje | H12: 3
A13: 12 | B13: T325ECN | C13: 46054.487 | D13: 2026-02-01 | E13: 46054.508 | F13: T325ECN => IDLING. At 01.02.2026 11:41:09 it moved with speed 0 km/h near 'T3, Copperbelt Province, Zambia, 10.04 km from Chingola'. | G13: T3, 10.04 km from Chingola | H13: 5
... A1161: 1160 | B1161: T941EBW | C1161: 46081.389 | D1161: 2026-02-28 | E1161: 46081.41 | F1161: T941EBW => IDLING. At 28.02.2026 09:20:45 it moved with speed 0 km/h near 'Rn1, Lualaba, Democratic Republic of the Congo, 2.48 km from Kaidi'. | G1161: Rn1, 2.48 km from Kaidi | H1161: 4

Sheet HARSH BRAKE VIOLATION
A1: SN | B1: Row Labels | C1: Event time | D1: RPT_DT | E1: DRIVER NAME | F1: Event text | G1: Location | H1: Count of Time received
A2: 1 | B2: T127EBX | C2: 46054.492 | D2: 2026-02-01 | E2: =VLOOKUP(Table2[[#This Row],[Row Labels]],[1]Sheet2!$B:$E,4,0) -> OMAR SWALEH CHANINGA | F2: T127EBX: Harsh braking has been activated. At 01.02.2026 11:48:04 it moved with speed 55 km/h near 'Great North Road, Muchinga Province, Zambia, 7.84 km from Chinunda'. | G2: Great North Road, Zambia, Muchinga Province, 7.84 km from Chinunda | H2: 3
A3: 2 | B3: T271EBY | C3: 46054.71 | D3: 2026-02-01 | E3: =VLOOKUP(Table2[[#This Row],[Row Labels]],[1]Sheet2!$B:$E,4,0) -> ISAYA MSHUKURU MMBANDO | F3: T271EBY: Harsh braking has been activated. At 01.02.2026 17:02:24 it moved with speed 66 km/h near 'Rn1, Haut-Katanga, Democratic Republic of the Congo, 11.59 km from Sumbilili'. | G3: Rn1, Democratic Republic of the Congo, Haut-Katanga, 11.59 km from Sumbilili | H3: 3
A4: 3 | B4: T282EBY | C4: 46054.276 | D4: 2026-02-01 | E4: =VLOOKUP(Table2[[#This Row],[Row Labels]],[1]Sheet2!$B:$E,4,0) -> SAID RAJABU RAJABU | F4: T282EBY: Harsh braking has been activated. At 01.02.2026 06:36:58 it moved with speed 54 km/h near 'Iringa Road, Lundamatwe, Iringa, Tanzania'. | G4: Lundamatwe, Iringa Road, Tanzania, Iringa | H4: 4
A5: 4 | B5: T331EBX | C5: 46054.558 | D5: 2026-02-01 | E5: =VLOOKUP(Table2[[#This Row],[Row Labels]],[1]Sheet2!$B:$E,4,0) -> YUSUFU SAMSON NICODEMUS | F5: T331EBX: Harsh braking has been activated. At 01.02.2026 13:23:51 it moved with speed 52 km/h near 'T1, Mswiswi, Mbeya, Tanzania'. | G5: Mswiswi, T1, Tanzania, Mbeya | H5: 3
A6: 5 | B6: T341EBX | C6: 46054.394 | D6: 2026-02-01 | E6: =VLOOKUP(Table2[[#This Row],[Row Labels]],[1]Sheet2!$B:$E,4,0) -> JAMES JOSEPH NJAU | F6: T341EBX: Harsh braking has been activated. At 01.02.2026 09:26:45 it moved with speed 51 km/h near 'Tanzania To Zambia Road, Iringa, Mufindi, Tanzania, 2.46 km from Ihemi'. | G6: Tanzania To Zambia Road, Tanzania, Iringa, Mufindi, 2.46 km from Ihemi | H6: 4
A7: 6 | B7: T407DHE | C7: 46054.524 | D7: 2026-02-01 | E7: =VLOOKUP(Table2[[#This Row],[Row Labels]],[1]Sheet2!$B:$E,4,0) -> RAJABU MOHAMED MATUA | F7: T407DHE: Harsh braking has been activated. At 01.02.2026 12:34:53 it moved with speed 56 km/h near 'Iringa Road, Morogoro, Kilosa, Tanzania, 2.90 km from Kidayi 'B''. | G7: Iringa Road, Tanzania, Morogoro, Kilosa, 2.90 km from Kidayi 'B' | H7: 11
A8: 7 | B8: T413DHG | C8: 46054.531 | D8: 2026-02-01 | E8: =VLOOKUP(Table2[[#This Row],[Row Labels]],[1]Sheet2!$B:$E,4,0) -> BASHIRU ABDALLA HUSSEIN | F8: T413DHG: Harsh braking has been activated. At 01.02.2026 12:45:14 it moved with speed 58 km/h near 'Great North Road, Central Province, Zambia, 2.83 km from Chifwefwe B'. | G8: Great North Road, Zambia, Central Province, 2.83 km from Chifwefwe B | H8: 6
A9: 8 | B9: T482DYR | C9: 46054.389 | D9: 2026-02-01 | E9: =VLOOKUP(Table2[[#This Row],[Row Labels]],[1]Sheet2!$B:$E,4,0) -> RAMADHANI SHABANI WAGAMOYO | F9: T482DYR: Harsh braking has been activated. At 01.02.2026 09:20:37 it moved with speed 55 km/h near 'M3, Northern Province, Zambia, 11.39 km from Makungwe'. | G9: M3, Zambia, Northern Province, 11.39 km from Makungwe | H9: 3
A10: 9 | B10: T494DYR | C10: 46054.602 | D10: 2026-02-01 | E10: =VLOOKUP(Table2[[#This Row],[Row Labels]],[1]Sheet2!$B:$E,4,0) -> GABRIEL SHIJA MAHONA | F10: T494DYR: Harsh braking has been activated. At 01.02.2026 14:26:44 it moved with speed 63 km/h near 'T1, Njombe, Tanzania, 10.30 km from Sao-Hill Forest Plantation'. | G10: T1, Tanzania, Njombe, 10.30 km from Sao-Hill Forest Plantation | H10: 5
A11: 10 | B11: T634DHL | C11: 46054.548 | D11: 2026-02-01 | E11: =VLOOKUP(Table2[[#This Row],[Row Labels]],[1]Sheet2!$B:$E,4,0) -> RAMADHANI MBEZI OMARY | F11: T634DHL: Harsh braking has been activated. At 01.02.2026 13:09:19 it moved with speed 65 km/h near 'Route De Lubumbashi, Haut-Katanga, Democratic Republic of the Congo, 2.29 km from Kapulwa'. | G11: Route De Lubumbashi, Democratic Republic of the Congo, Haut-Katanga, 2.29 km from Kapulwa | H11: 3
A12: 11 | B12: T712DYR | C12: 46054.376 | D12: 2026-02-01 | E12: =VLOOKUP(Table2[[#This Row],[Row Labels]],[1]Sheet2!$B:$E,4,0) -> RAJABU HUSSEIN AHMAD | F12: T712DYR: Harsh braking has been activated. At 01.02.2026 09:00:59 it moved with speed 52 km/h near 'T1, Mswiswi, Mbeya, Tanzania'. | G12: Mswiswi, T1, Tanzania, Mbeya | H12: 4
A13: 12 | B13: T250EBX | C13: 46055.482 | D13: 2026-02-02 | E13: =VLOOKUP(Table2[[#This Row],[Row Labels]],[1]Sheet2!$B:$E,4,0) -> FRANCIS ERNEST KIBULA | F13: T250EBX: Harsh braking has been activated. At 02.02.2026 11:33:39 it moved with speed 68 km/h near 'Iringa Road, Iringa, Tanzania, Mtandika 'B''. | G13: Iringa Road, Tanzania, Iringa, Mtandika 'B' | H13: 27
... A21: 20 | B21: T107EBX | C21: 46056.499 | D21: 2026-02-03 | E21: =VLOOKUP(Table2[[#This Row],[Row Labels]],[1]Sheet2!$B:$E,4,0) -> GODFREY JOHN ANTHONY KUNDI | F21: T107EBX: Harsh braking has been activated. At 03.02.2026 11:58:49 it moved with speed 56 km/h near 'Great North Road, Central Province, Zambia, 3.45 km from Kanona'. | G21: Great North Road, Zambia, Central Province, 3.45 km from Kanona | H21: 4
A22: 21 | B22: T191EBX | C22: 46056.338 | D22: 2026-02-03 | E22: =VLOOKUP(Table2[[#This Row],[Row Labels]],[1]Sheet2!$B:$E,4,0) -> ISAYA JOHN MSENA | G22: Great North Road, Zambia, Central Province, 11.27 km from Kanona | H22: 4
A23: 22 | B23: T232EBX | C23: 46056.363 | D23: 2026-02-03 | E23: =VLOOKUP(Table2[[#This Row],[Row Labels]],[1]Sheet2!$B:$E,4,0) -> ELIAH YUSUPH MPANGO | F23: T191EBX: Harsh braking has been activated. At 03.02.2026 08:06:44 it moved with speed 60 km/h near 'Great North Road, Central Province, Zambia, 11.27 km from Kanona'. | G23: Iringa Road, Tanzania, Morogoro, Kilosa, 2.06 km from Mikumi | H23: 5
A24: 23 | B24: T329ECN | C24: 46056.375 | D24: 2026-02-03 | E24: =VLOOKUP(Table2[[#This Row],[Row Labels]],[1]Sheet2!$B:$E,4,0) -> JUMA KOBA SAID | F24: T329ECN: Harsh braking has been activated. At 03.02.2026 08:59:41 it moved with speed 53 km/h near 'Great North Road, Muchinga Province, Zambia, 7.88 km from Chinunda'. | G24: Great North Road, Zambia, Muchinga Province, 7.88 km from Chinunda | H24: 5
A25: 24 | B25: T385ECN | C25: 46056.314 | D25: 2026-02-03 | E25: =VLOOKUP(Table2[[#This Row],[Row Labels]],[1]Sheet2!$B:$E,4,0) -> CHARLES LONGIN MASESA | F25: T329ECN: Harsh braking has been activated. At 03.02.2026 08:59:41 it moved with speed 53 km/h near 'Great North Road, Muchinga Province, Zambia, 7.88 km from Chinunda'. | G25: Great North Road, Zambia, Central Province, 11.79 km from Kanona | H25: 3
A26: 25 | B26: T572DYR | C26: 46056.266 | D26: 2026-02-03 | E26: =VLOOKUP(Table2[[#This Row],[Row Labels]],[1]Sheet2!$B:$E,4,0) -> ISMAIL KISANDU RUBASHA | F26: T572DYR: Harsh braking has been activated. At 03.02.2026 06:23:26 it moved with speed 61 km/h near 'Iringa Road, Morogoro, Kilosa, Tanzania, Kidayi 'B''. | G26: Iringa Road, Tanzania, Morogoro, Kilosa, Kidayi 'B' | H26: 3
A27: 26 | B27: T728DYR | C27: 46056.272 | D27: 2026-02-03 | E27: =VLOOKUP(Table2[[#This Row],[Row Labels]],[1]Sheet2!$B:$E,4,0) -> ELIA JUMA NZOWA | F27: T728DYR: Harsh braking has been activated. At 03.02.2026 06:32:10 it moved with speed 60 km/h near 'T1, Pwani, Bagamoyo, Tanzania, Msolwa'. | G27: T1, Tanzania, Pwani, Bagamoyo, Msolwa | H27: 4
A28: 27 | B28: T861EBY | C28: 46056.485 | D28: 2026-02-03 | E28: =VLOOKUP(Table2[[#This Row],[Row Labels]],[1]Sheet2!$B:$E,4,0) -> OMARY SAID MTAJI | F28: T861EBY: Harsh braking has been activated. At 03.02.2026 11:37:55 it moved with speed 53 km/h near 'Morogoro Main Road, Pwani, Kibaha, Tanzania, Ruvu Darajani'. | G28: Morogoro Main Road, Tanzania, Pwani, Kibaha, Ruvu Darajani | H28: 4
A29: 28 | B29: T862EBY | C29: 46056.317 | D29: 2026-02-03 | E29: =VLOOKUP(Table2[[#This Row],[Row Labels]],[1]Sheet2!$B:$E,4,0) -> ABDULHAFIDH RADMAN ALLY | F29: T862EBY: Harsh braking has been activated. At 03.02.2026 07:35:58 it moved with speed 58 km/h near 'Great North Road, Central Province, Zambia, 13.65 km from Kanona'. | G29: Great North Road, Zambia, Central Province, 13.65 km from Kanona | H29: 3
A30: 29 | B30: T905EBW | C30: 46056.423 | D30: 2026-02-03 | E30: =VLOOKUP(Table2[[#This Row],[Row Labels]],[1]Sheet2!$B:$E,4,0) -> ALLY RASHID SAID | F30: T862EBY: Harsh braking has been activated. At 03.02.2026 07:35:58 it moved with speed 58 km/h near 'Great North Road, Central Province, Zambia, 13.65 km from Kanona'. | G30: Great North Road, Zambia, Central Province, 17.50 km from Ndabala | H30: 4
A31: 30 | B31: T914EBW | C31: 46056.513 | D31: 2026-02-03 | E31: =VLOOKUP(Table2[[#This Row],[Row Labels]],[1]Sheet2!$B:$E,4,0) -> SALIMU SAIDI KIANDIKO | F31: T862EBY: Harsh braking has been activated. At 03.02.2026 07:35:58 it moved with speed 58 km/h near 'Great North Road, Central Province, Zambia, 13.65 km from Kanona'. | G31: Great North Road, Zambia, Central Province, 13.38 km from Muchinka | H31: 3
A32: 31 | B32: T153EBX | C32: 46057.311 | D32: 2026-02-04 | E32: =VLOOKUP(Table2[[#This Row],[Row Labels]],[1]Sheet2!$B:$E,4,0) -> BAHATI ATHUMANI MDOE | F32: T153EBX: Harsh braking has been activated. At 04.02.2026 07:27:23 it moved with speed 57 km/h near 'Great North Road, Muchinga Province, Zambia, 8.67 km from Mwezo'. | G32: Great North Road, Zambia, Muchinga Province, 8.67 km from Mwezo | H32: 4
A33: 32 | B33: T263EBX | C33: 46057.261 | D33: 2026-02-04 | E33: =VLOOKUP(Table2[[#This Row],[Row Labels]],[1]Sheet2!$B:$E,4,0) -> BAKARI MOHAMEDI SAIDI | F33: T263EBX: Harsh braking has been activated. At 04.02.2026 06:16:25 it moved with speed 62 km/h near 'Great North Road, Central Province, Zambia, 12.06 km from Muchinka'. | G33: Great North Road, Zambia, Central Province, 12.06 km from Muchinka | H33: 4
A34: 33 | B34: T271EBY | C34: 46057.326 | D34: 2026-02-04 | E34: =VLOOKUP(Table2[[#This Row],[Row Labels]],[1]Sheet2!$B:$E,4,0) -> ISAYA MSHUKURU MMBANDO | F34: T271EBY: Harsh braking has been activated. At 04.02.2026 07:49:55 it moved with speed 52 km/h near 'T3, Copperbelt Province, Zambia, Ndola'. | G34: T3, Zambia, Copperbelt Province, Ndola | H34: 3
... A311: 310 | B311: T952DSX | C311: 46081.421 | D311: 2026-02-28 | E311: =VLOOKUP(Table2[[#This Row],[Row Labels]],[1]Sheet2!$B:$E,4,0) -> SAMSONI JOSEPH USEGA | F311: T952DSX: Harsh braking has been activated. At 28.02.2026 10:06:39 it moved with speed 62 km/h near 'Great North Road, Muchinga Province, Zambia, 10.01 km from Isoka'. | G311: Great North Road, Zambia, Muchinga Province, 10.01 km from Isoka | H311: 4

Sheet  OVER SPEEDING VIOLATION 
A1: SN | B1: TRUCK NO | C1: Time | D1: RPT_DT | E1: DRIVER NAME | F1: MAX SPEED | G1: Location | H1: Speed limit | I1: Count
A2: 1 | B2: T259EBX | C2: 01.02.2026 11:05:42 am | D2: 01.02.2026 | E2: =VLOOKUP(Table1[[#This Row],[TRUCK NO ]],[1]Sheet2!$B:$E,4,0) -> ABDUL NASSORO SELEMANI | F2: 101 km/h | G2: DANGER ZONE BUNGU-BUNGU TO TUMBWE - THEFTS!!!!! | H2: 81 km/h | I2: 12
A3: 2 | B3: T263DDJ | C3: 01.02.2026 06:54:12 pm | D3: 01.02.2026 | E3: =VLOOKUP(Table1[[#This Row],[TRUCK NO ]],[1]Sheet2!$B:$E,4,0) -> SAIMON GEORGE KAAYA | F3: 88 km/h | G3: T1, Njombe, Tanzania, 3.43 km from Nyololo | H3: 81 km/h | I3: 1
A4: 3 | B4: T271EBY | C4: 01.02.2026 08:18:47 am | D4: 01.02.2026 | E4: =VLOOKUP(Table1[[#This Row],[TRUCK NO ]],[1]Sheet2!$B:$E,4,0) -> ISAYA MSHUKURU MMBANDO | F4: 88 km/h | G4: LUBUMBASHI | H4: 81 km/h | I4: 8
A5: 4 | B5: T314DDJ | C5: 01.02.2026 10:05:02 am | D5: 01.02.2026 | E5: =VLOOKUP(Table1[[#This Row],[TRUCK NO ]],[1]Sheet2!$B:$E,4,0) -> MWIDIN DANIEL MALATO | F5: 94 km/h | G5: Great North Road, Muchinga Province, Zambia, 6.63 km from Amosi Pumba | H5: 81 km/h | I5: 3
A6: 5 | B6: T332DHG | C6: 01.02.2026 05:20:15 pm | D6: 01.02.2026 | E6: =VLOOKUP(Table1[[#This Row],[TRUCK NO ]],[1]Sheet2!$B:$E,4,0) -> AHMED JAFARI SHILANGILA | F6: 90 km/h | G6: KASUMBALESA - SAKANIA RD | H6: 81 km/h | I6: 3
A7: 6 | B7: T434DHG | C7: 01.02.2026 03:49:33 pm | D7: 01.02.2026 | E7: =VLOOKUP(Table1[[#This Row],[TRUCK NO ]],[1]Sheet2!$B:$E,4,0) -> MARTIN ANTHONI SANGA | F7: 88 km/h | G7: Rn1, Lualaba, Democratic Republic of the Congo, 3.00 km from Kazelo | H7: 81 km/h | I7: 2
A8: 7 | B8: T572DEB | C8: 01.02.2026 11:18:47 am | D8: 01.02.2026 | E8: =VLOOKUP(Table1[[#This Row],[TRUCK NO ]],[1]Sheet2!$B:$E,4,0) -> MUSSA AHAMADI NAMBAYAYA | F8: 98 km/h | G8: SERENJE | H8: 81 km/h | I8: 1
A9: 8 | B9: T579DTQ | C9: 01.02.2026 12:01:19 pm | D9: 01.02.2026 | E9: =VLOOKUP(Table1[[#This Row],[TRUCK NO ]],[1]Sheet2!$B:$E,4,0) -> MICHAEL BONIVENTURA SHANGO | F9: 89 km/h | G9: Rn1, Haut-Katanga, Democratic Republic of the Congo, 7.34 km from Lwisha | H9: 81 km/h | I9: 2
A10: 9 | B10: T595DTQ | C10: 01.02.2026 09:58:38 am | D10: 01.02.2026 | E10: =VLOOKUP(Table1[[#This Row],[TRUCK NO ]],[1]Sheet2!$B:$E,4,0) -> MNAWARU AHMADA BYEMPISI | F10: 99 km/h | G10: Great North Road, Muchinga Province, Zambia, 10.25 km from Chinunda | H10: 81 km/h | I10: 11
A11: 10 | B11: T634DHL | C11: 01.02.2026 12:30:14 pm | D11: 01.02.2026 | E11: =VLOOKUP(Table1[[#This Row],[TRUCK NO ]],[1]Sheet2!$B:$E,4,0) -> RAMADHANI MBEZI OMARY | F11: 86 km/h | G11: DANGER ZONE BUNGU-BUNGU TO TUMBWE - THEFTS!!!!! | H11: 81 km/h | I11: 4
A12: 11 | B12: T876EBW | C12: 01.02.2026 08:56:33 am | D12: 01.02.2026 | E12: =VLOOKUP(Table1[[#This Row],[TRUCK NO ]],[1]Sheet2!$B:$E,4,0) -> KHALFANI EMMANUEL MUHIGI | F12: 98 km/h | G12: Rn39, Lualaba, Democratic Republic of the Congo, Kamipungu | H12: 81 km/h | I12: 3
A13: 12 | B13: T148EBX | C13: 02.02.2026 01:00:52 pm | D13: 02.02.2026 | E13: =VLOOKUP(Table1[[#This Row],[TRUCK NO ]],[1]Sheet2!$B:$E,4,0) -> BOAZI GWILA MAKALANGA | F13: 88 km/h | G13: Great North Road, Muchinga Province, Zambia, 8.58 km from Chifumbula | H13: 81 km/h | I13: 2
... A216: 215 | B216: T915EBW | C216: 28.02.2026 07:32:56 am | D216: 28.02.2026 | E216: =VLOOKUP(Table1[[#This Row],[TRUCK NO ]],[1]Sheet2!$B:$E,4,0) -> GODFREY FRANK MBOJA | F216: 89 km/h | G216: Rn39, Lualaba, Democratic Republic of the Congo, Kampulu | H216: 81 km/h | I216: 4

Sheet NIGHT DRIVING REPORT 
A1: Vehicle no | B1: Driver name | C1: TM NAME | D1: TC NAME | E1: Beginning | F1: RPT_DT | G1: Initial location | H1: End | I1: Final location | J1: DURATION | K1: Mileage | L1: Offense
A2: T415DHE | B2: =VLOOKUP(Table4[[#This Row],[Vehicle no]],[1]Sheet2!$B:$J,4,0) -> SHUKURU MARTIN SANGA | C2: =VLOOKUP(Table4[[#This Row],[Vehicle no]],[1]Sheet2!$B:$J,9,0) -> IRENE SHIJA | D2: =VLOOKUP(Table4[[#This Row],[Vehicle no]],[1]Sheet2!$B:$J,8,0) -> 116-410-346 | E2: 46054.231 | F2: 2026-02-01 | G2: T1, Mlowo | H2: 46054.294 | I2: TUNDUMA PARKING | J2: 1:02:47 | K2: 35.28 km | L2: Early start
A3: T439DHG | B3: =VLOOKUP(Table4[[#This Row],[Vehicle no]],[1]Sheet2!$B:$J,4,0) -> AMINI JUMA AHMADI | C3: =VLOOKUP(Table4[[#This Row],[Vehicle no]],[1]Sheet2!$B:$J,9,0) -> LUSAJO KASUNGA | D3: =VLOOKUP(Table4[[#This Row],[Vehicle no]],[1]Sheet2!$B:$J,8,0) -> 131-255675 | E3: 46054.233 | F3: 2026-02-01 | G3: Tanzania To Zambia Road, 2.24 km from Mafinga | H3: 46054.378 | I3: T1, Mayale | J3: 3:11:42 | K3: 112.36 km | L3: Early start
A4: T518DEB | B4: =VLOOKUP(Table4[[#This Row],[Vehicle no]],[1]Sheet2!$B:$J,4,0) -> JAMES RASHIDI GWAU | C4: =VLOOKUP(Table4[[#This Row],[Vehicle no]],[1]Sheet2!$B:$J,9,0) -> Martha GOLODI | D4: =VLOOKUP(Table4[[#This Row],[Vehicle no]],[1]Sheet2!$B:$J,8,0) -> 0 | E4: 46054.233 | F4: 2026-02-01 | G4: Tanzania To Zambia Road, 2.24 km from Mafinga | H4: 46054.385 | I4: T1, Mayale | J4: 3:14:10 | K4: 112.27 km | L4: Early start
A5: T795DDS | B5: =VLOOKUP(Table4[[#This Row],[Vehicle no]],[1]Sheet2!$B:$J,4,0) -> HAMIS BUNDALA IZINA | C5: =VLOOKUP(Table4[[#This Row],[Vehicle no]],[1]Sheet2!$B:$J,9,0) -> PLASDUS MAHUMBA | D5: =VLOOKUP(Table4[[#This Row],[Vehicle no]],[1]Sheet2!$B:$J,8,0) -> 115-917-447 | E5: 46054.217 | F5: 2026-02-01 | G5: Iringa Road, Kikwaraza | H5: 46054.298 | I5: Iringa Road, 1.24 km from Ruaha Mbuyumi | J5: 1:56:57 | K5: 76.61 km | L5: Early start
A6: T514DTR | B6: =VLOOKUP(Table4[[#This Row],[Vehicle no]],[1]Sheet2!$B:$J,4,0) -> IBRAHIM MWINSHEHE KILAKALA | C6: =VLOOKUP(Table4[[#This Row],[Vehicle no]],[1]Sheet2!$B:$J,9,0) -> PLASDUS MAHUMBA | D6: =VLOOKUP(Table4[[#This Row],[Vehicle no]],[1]Sheet2!$B:$J,8,0) -> #N/A | E6: 46055.237 | F6: 2026-02-02 | G6: MAKAMBAKO | H6: 46055.424 | I6: IPOGOLO IRINGA | J6: 3:40:41 | K6: 153.85 km | L6: Early start
A7: T645DHL | B7: =VLOOKUP(Table4[[#This Row],[Vehicle no]],[1]Sheet2!$B:$J,4,0) -> ISIHAKA IDRISA HAMIDU | C7: =VLOOKUP(Table4[[#This Row],[Vehicle no]],[1]Sheet2!$B:$J,9,0) -> SADI KIMWAGA | D7: =VLOOKUP(Table4[[#This Row],[Vehicle no]],[1]Sheet2!$B:$J,8,0) -> 112-800-034 | E7: 46055.913 | F7: 2026-02-02 | G7: T3, 10.55 km from Chingola | H7: 46056 | I7: CHINGOLA, ZAMBIA | J7: 0:16:11 | K7: 3.80 km | L7: Night driving
A8: T346EBX | B8: =VLOOKUP(Table4[[#This Row],[Vehicle no]],[1]Sheet2!$B:$J,4,0) -> LAIZER DOMINIKUS MANDIKE | C8: =VLOOKUP(Table4[[#This Row],[Vehicle no]],[1]Sheet2!$B:$J,9,0) -> LUSAJO KASUNGA | D8: =VLOOKUP(Table4[[#This Row],[Vehicle no]],[1]Sheet2!$B:$J,8,0) -> #N/A | E8: 46056.211 | F8: 2026-02-03 | G8: T1, Ruvu Darajani | H8: 46056.318 | I8: MBAGALA YARD | J8: 2:35:17 | K8: 79.72 km | L8: Early start
A9: T263EBX | B9: =VLOOKUP(Table4[[#This Row],[Vehicle no]],[1]Sheet2!$B:$J,4,0) -> BAKARI MOHAMEDI SAIDI | C9: =VLOOKUP(Table4[[#This Row],[Vehicle no]],[1]Sheet2!$B:$J,9,0) -> LUSAJO KASUNGA | D9: =VLOOKUP(Table4[[#This Row],[Vehicle no]],[1]Sheet2!$B:$J,8,0) -> 102-227-107 | E9: 46057.227 | F9: 2026-02-04 | G9: SERENJE | H9: 46057.919 | I9: TUNDUMA PARKING | J9: 5:15:16 | K9: 263.39 km | L9: Early start
A10: T586DYR | B10: =VLOOKUP(Table4[[#This Row],[Vehicle no]],[1]Sheet2!$B:$J,4,0) -> MATHIAS ISDORY MGOMBE | C10: =VLOOKUP(Table4[[#This Row],[Vehicle no]],[1]Sheet2!$B:$J,9,0) -> LUSAJO KASUNGA | D10: =VLOOKUP(Table4[[#This Row],[Vehicle no]],[1]Sheet2!$B:$J,8,0) -> 111297576 | E10: 46057.232 | F10: 2026-02-04 | G10: IGUMBILO, IRINGA | H10: 46057.417 | I10: Iringa Road, Mikumi | J10: 4:15:32 | K10: 177.29 km | L10: Early start
A11: T779EBW | B11: =VLOOKUP(Table4[[#This Row],[Vehicle no]],[1]Sheet2!$B:$J,4,0) -> PAUL NKAMU SENGWA | C11: =VLOOKUP(Table4[[#This Row],[Vehicle no]],[1]Sheet2!$B:$J,9,0) -> Ayoub BENESTA | D11: =VLOOKUP(Table4[[#This Row],[Vehicle no]],[1]Sheet2!$B:$J,8,0) -> 111917663 | E11: 46057.224 | F11: 2026-02-04 | G11: T1, Kwalaza | H11: 46057.39 | I11: T1, Mkambarani | J11: 3:28:46 | K11: 103.77 km | L11: Early start
A12: T148EBX | B12: =VLOOKUP(Table4[[#This Row],[Vehicle no]],[1]Sheet2!$B:$J,4,0) -> BOAZI GWILA MAKALANGA | C12: =VLOOKUP(Table4[[#This Row],[Vehicle no]],[1]Sheet2!$B:$J,9,0) -> Ayoub BENESTA | D12: =VLOOKUP(Table4[[#This Row],[Vehicle no]],[1]Sheet2!$B:$J,8,0) -> 117784944 | E12: 46058.232 | F12: 2026-02-05 | G12: IFUNDA, IRINGA | H12: 46058.953 | I12: GL KURASINI YARD | J12: 8:09:09 | K12: 285.22 km | L12: Early start
A13: T573DYR | B13: =VLOOKUP(Table4[[#This Row],[Vehicle no]],[1]Sheet2!$B:$J,4,0) -> RICHARD OMBENI KIOGWE | C13: =VLOOKUP(Table4[[#This Row],[Vehicle no]],[1]Sheet2!$B:$J,9,0) -> Ayoub BENESTA | D13: =VLOOKUP(Table4[[#This Row],[Vehicle no]],[1]Sheet2!$B:$J,8,0) -> 111-718-776 | E13: 46058.234 | F13: 2026-02-05 | G13: ILULA SOKONI | H13: 46058.379 | I13: Iringa Road, Tambuka Reli | J13: 3:29:32 | K13: 140.45 km | L13: Early start
... A45: T734EBX | B45: =VLOOKUP(Table4[[#This Row],[Vehicle no]],[1]Sheet2!$B:$J,4,0) -> EZEKIEL AIZACK KIHANZA | C45: =VLOOKUP(Table4[[#This Row],[Vehicle no]],[1]Sheet2!$B:$J,9,0) -> PLASDUS MAHUMBA | D45: =VLOOKUP(Table4[[#This Row],[Vehicle no]],[1]Sheet2!$B:$J,8,0) -> 115168665 | E45: 46068.236 | F45: 2026-02-15 | G45: IFUNDA, IRINGA | H45: 46068.355 | I45: ILULA SOKONI | J45: 2:20:02 | K45: 80.36 km | L45: Early start
A46: T749DEB | B46: =VLOOKUP(Table4[[#This Row],[Vehicle no]],[1]Sheet2!$B:$J,4,0) -> N/A | C46: =VLOOKUP(Table4[[#This Row],[Vehicle no]],[1]Sheet2!$B:$J,9,0) -> SADI KIMWAGA | D46: =VLOOKUP(Table4[[#This Row],[Vehicle no]],[1]Sheet2!$B:$J,8,0) -> #N/A | E46: 2/15/2026 15:40:21 PM | F46: 2026-02-15 | G46: KAPIRI DANGER ZONE | H46: 2/15/2026 17:40:19 PM | I46: NDOLA | J46: 2:00 | K46: 120.5 km | L46: Driving Without Convoy Day
A47: T435DHG | B47: =VLOOKUP(Table4[[#This Row],[Vehicle no]],[1]Sheet2!$B:$J,4,0) -> OTHUMAN SALUM MSIKA | C47: =VLOOKUP(Table4[[#This Row],[Vehicle no]],[1]Sheet2!$B:$J,9,0) -> IRENE SHIJA | D47: =VLOOKUP(Table4[[#This Row],[Vehicle no]],[1]Sheet2!$B:$J,8,0) -> 111-885-796 | E47: 46069.896 | F47: 2026-02-16 | G47: M3, 10.45 km from Shikasenge | H47: 46069.936 | I47: KASAMA, ZAMBIA | J47: 0:57:00 | K47: 32.16 km | L47: Night driving
A48: T582DTQ | B48: =VLOOKUP(Table4[[#This Row],[Vehicle no]],[1]Sheet2!$B:$J,4,0) -> MOUD KIMWELI MUSSA | C48: =VLOOKUP(Table4[[#This Row],[Vehicle no]],[1]Sheet2!$B:$J,9,0) -> PLASDUS MAHUMBA | D48: =VLOOKUP(Table4[[#This Row],[Vehicle no]],[1]Sheet2!$B:$J,8,0) -> #N/A | E48: 46069.96 | F48: 2026-02-16 | G48: LUBUMBASHI | H48: 46069.985 | I48: GENERAL PARKING - LUBUMBASHI | J48: 0:36:08 | K48: 21.49 km | L48: Night driving
A49: T660DTQ | B49: =VLOOKUP(Table4[[#This Row],[Vehicle no]],[1]Sheet2!$B:$J,4,0) -> ALLY ALIAMINI MSAMI | C49: =VLOOKUP(Table4[[#This Row],[Vehicle no]],[1]Sheet2!$B:$J,9,0) -> SADI KIMWAGA | D49: =VLOOKUP(Table4[[#This Row],[Vehicle no]],[1]Sheet2!$B:$J,8,0) -> #N/A | E49: 46069.982 | F49: 2026-02-16 | G49: LUBUMBASHI | H49: 46070 | I49: LUBUMBASHI | J49: 0:26:21 | K49: 9.65 km | L49: Night driving
A50: T727DYR | B50: =VLOOKUP(Table4[[#This Row],[Vehicle no]],[1]Sheet2!$B:$J,4,0) -> ZACHALIA JOSEPH SHIMBI | C50: =VLOOKUP(Table4[[#This Row],[Vehicle no]],[1]Sheet2!$B:$J,9,0) -> PLASDUS MAHUMBA | D50: =VLOOKUP(Table4[[#This Row],[Vehicle no]],[1]Sheet2!$B:$J,8,0) -> #N/A | E50: 46069.982 | F50: 2026-02-16 | G50: LUBUMBASHI | H50: 46070 | I50: LUBUMBASHI | J50: 0:25:08 | K50: 9.99 km | L50: Night driving
A51: T764DYR | B51: =VLOOKUP(Table4[[#This Row],[Vehicle no]],[1]Sheet2!$B:$J,4,0) -> OPTATUS SYLVESTER MUHINDO | C51: =VLOOKUP(Table4[[#This Row],[Vehicle no]],[1]Sheet2!$B:$J,9,0) -> PLASDUS MAHUMBA | D51: =VLOOKUP(Table4[[#This Row],[Vehicle no]],[1]Sheet2!$B:$J,8,0) -> #N/A | E51: 46069.96 | F51: 2026-02-16 | G51: LUBUMBASHI | H51: 46069.985 | I51: GENERAL PARKING - LUBUMBASHI | J51: 0:36:45 | K51: 21.55 km | L51: Night driving
A52: T378DHG | B52: =VLOOKUP(Table4[[#This Row],[Vehicle no]],[1]Sheet2!$B:$J,4,0) -> ENOCK ADRIANO MUSHI | C52: =VLOOKUP(Table4[[#This Row],[Vehicle no]],[1]Sheet2!$B:$J,9,0) -> IRENE SHIJA | D52: =VLOOKUP(Table4[[#This Row],[Vehicle no]],[1]Sheet2!$B:$J,8,0) -> 125-578-209 | E52: 46071.224 | F52: 2026-02-18 | G52: T2, Mkata | H52: 46071.383 | I52: KANGE PARKING - TANGA | J52: 3:27:41 | K52: 127.28 km | L52: Early start
A53: T793DYR | B53: =VLOOKUP(Table4[[#This Row],[Vehicle no]],[1]Sheet2!$B:$J,4,0) -> AMIRI TALIB SHEIN | C53: =VLOOKUP(Table4[[#This Row],[Vehicle no]],[1]Sheet2!$B:$J,9,0) -> PLASDUS MAHUMBA | D53: =VLOOKUP(Table4[[#This Row],[Vehicle no]],[1]Sheet2!$B:$J,8,0) -> #N/A | E53: 46071.917 | F53: 2026-02-18 | G53: M1, 12.91 km from Sementi | H53: 46071.997 | I53: Mbala - Nakonde Road, 13.42 km from Chilundumuzi | J53: 1:56:06 | K53: 115.11 km | L53: Night driving
A54: T586DYR | B54: =VLOOKUP(Table4[[#This Row],[Vehicle no]],[1]Sheet2!$B:$J,4,0) -> MATHIAS ISDORY MGOMBE | C54: =VLOOKUP(Table4[[#This Row],[Vehicle no]],[1]Sheet2!$B:$J,9,0) -> LUSAJO KASUNGA | D54: =VLOOKUP(Table4[[#This Row],[Vehicle no]],[1]Sheet2!$B:$J,8,0) -> 111297576 | E54: 46072.235 | F54: 2026-02-19 | G54: Tanzam Road, 2.29 km from Mbeya | H54: 46072.388 | I54: TUNDUMA PARKING | J54: 3:26:47 | K54: 93.44 km | L54: Early start
A55: T311EBX | B55: =VLOOKUP(Table4[[#This Row],[Vehicle no]],[1]Sheet2!$B:$J,4,0) -> NASSORO ALLY AMBALI | C55: =VLOOKUP(Table4[[#This Row],[Vehicle no]],[1]Sheet2!$B:$J,9,0) -> Ayoub BENESTA | D55: =VLOOKUP(Table4[[#This Row],[Vehicle no]],[1]Sheet2!$B:$J,8,0) -> 112217495 | E55: 46073.903 | F55: 2026-02-20 | G55: Rn1, 1.76 km from Kasumbalesa | H55: 46073.976 | I55: WHISKY DRC | J55: 0:32:40 | K55: 0.79 km | L55: Night driving
A56: T435DHG | B56: =VLOOKUP(Table4[[#This Row],[Vehicle no]],[1]Sheet2!$B:$J,4,0) -> OTHUMAN SALUM MSIKA | C56: =VLOOKUP(Table4[[#This Row],[Vehicle no]],[1]Sheet2!$B:$J,9,0) -> IRENE SHIJA | D56: =VLOOKUP(Table4[[#This Row],[Vehicle no]],[1]Sheet2!$B:$J,8,0) -> 111-885-796 | E56: 46073.212 | F56: 2026-02-20 | G56: IGURUSI | H56: 46073.841 | I56: T1, Bwawani | J56: 14:36:42 | K56: 624.65 km | L56: Early start
A57: T498DYR | B57: =VLOOKUP(Table4[[#This Row],[Vehicle no]],[1]Sheet2!$B:$J,4,0) -> MUSSA OMARY HAMZA | C57: =VLOOKUP(Table4[[#This Row],[Vehicle no]],[1]Sheet2!$B:$J,9,0) -> Martha GOLODI | D57: =VLOOKUP(Table4[[#This Row],[Vehicle no]],[1]Sheet2!$B:$J,8,0) -> #N/A | E57: 46073.23 | F57: 2026-02-20 | G57: MAKAMBAKO | H57: 46073.367 | I57: Tanzania To Zambia Road, 2.87 km from Ugwachanya | J57: 2:50:10 | K57: 140.73 km | L57: Early start
A58: T588DTQ | B58: =VLOOKUP(Table4[[#This Row],[Vehicle no]],[1]Sheet2!$B:$J,4,0) -> RAMADHANI SALIMU SHEDAFA | C58: =VLOOKUP(Table4[[#This Row],[Vehicle no]],[1]Sheet2!$B:$J,9,0) -> Ayoub BENESTA | D58: =VLOOKUP(Table4[[#This Row],[Vehicle no]],[1]Sheet2!$B:$J,8,0) -> 113000848 | E58: 46073.234 | F58: 2026-02-20 | G58: MAKAMBAKO WBG | H58: 46073.476 | I58: Iringa Road, 3.87 km from Ikokoto | J58: 5:39:57 | K58: 215.17 km | L58: Early start
... A68: T871EBY | B68: =VLOOKUP(Table4[[#This Row],[Vehicle no]],[1]Sheet2!$B:$J,4,0) -> ATANASI PETRO MAGOHE | C68: =VLOOKUP(Table4[[#This Row],[Vehicle no]],[1]Sheet2!$B:$J,9,0) -> SADI KIMWAGA | D68: =VLOOKUP(Table4[[#This Row],[Vehicle no]],[1]Sheet2!$B:$J,8,0) -> 130721125 | E68: 46076.222 | F68: 2026-02-23 | G68: T1, Ruvu Darajani | H68: 46076.374 | I68: DAR ES SALAAM | J68: 2:11:38 | K68: 63.98 km | L68: Early start
A69: T263DDJ | B69: =VLOOKUP(Table4[[#This Row],[Vehicle no]],[1]Sheet2!$B:$J,4,0) -> SAIMON GEORGE KAAYA | C69: =VLOOKUP(Table4[[#This Row],[Vehicle no]],[1]Sheet2!$B:$J,9,0) -> LUSAJO KASUNGA | D69: =VLOOKUP(Table4[[#This Row],[Vehicle no]],[1]Sheet2!$B:$J,8,0) -> #N/A | E69: 2026-02-23 21:17:30 | F69: =LEFT(E:E,10) -> 2026-02-23 | G69: Rn39, 5.54 km from Kisenda | H69: 2026-02-23 22:45:00 | I69: Route De La Mine Deziwa, 5.69 km from Kisenda | J69: 1:27:30 | K69: 16.710143 | L69: Night driving
A70: T993EBW | B70: =VLOOKUP(Table4[[#This Row],[Vehicle no]],[1]Sheet2!$B:$J,4,0) -> RAJABU KONGO LADISLAUS | C70: =VLOOKUP(Table4[[#This Row],[Vehicle no]],[1]Sheet2!$B:$J,9,0) -> SADI KIMWAGA | D70: =VLOOKUP(Table4[[#This Row],[Vehicle no]],[1]Sheet2!$B:$J,8,0) -> 112304606 | E70: =VLOOKUP(A70,[2]TRIPS!A:G,2,) -> 2026-02-23 20:45:42 | F70: =LEFT(E:E,10) -> 2026-02-23 | G70: =VLOOKUP(A70,[2]TRIPS!A:G,3,) -> WENDA WBG | H70: =VLOOKUP(A70,[2]TRIPS!A:G,4,) -> 2026-02-23 21:45:29 | I70: =VLOOKUP(A70,[2]TRIPS!A:G,5,) -> Dar - Mbeya Highway, Ndiuka | J70: =VLOOKUP(A70,[2]TRIPS!A:G,6,) -> 0:32:45 | K70: =VLOOKUP(A70,[2]TRIPS!A:G,7,) -> 20.174108 | L70: Night driving
A71: T267DDJ | B71: =VLOOKUP(Table4[[#This Row],[Vehicle no]],[1]Sheet2!$B:$J,4,0) -> KITENGU HAMISI KITENGU | C71: =VLOOKUP(Table4[[#This Row],[Vehicle no]],[1]Sheet2!$B:$J,9,0) -> Martha GOLODI | D71: =VLOOKUP(Table4[[#This Row],[Vehicle no]],[1]Sheet2!$B:$J,8,0) -> 0 | E71: 46077.91 | F71: 2026-02-24 | G71: Mbeya City, Tanzam Road | H71: 46078 | I71: Mambi | J71: 2:08:39 | K71: 61.00 km | L71: Night driving
A72: T378DHG | B72: =VLOOKUP(Table4[[#This Row],[Vehicle no]],[1]Sheet2!$B:$J,4,0) -> ENOCK ADRIANO MUSHI | C72: =VLOOKUP(Table4[[#This Row],[Vehicle no]],[1]Sheet2!$B:$J,9,0) -> IRENE SHIJA | D72: =VLOOKUP(Table4[[#This Row],[Vehicle no]],[1]Sheet2!$B:$J,8,0) -> 125-578-209 | E72: 46077.208 | F72: 2026-02-24 | G72: Mbeya City, Mahakama Avenue | H72: 46077.374 | I72: TUNDUMA PARKING | J72: 3:45:15 | K72: 93.21 km | L72: Early start
A73: T406DHG | B73: =VLOOKUP(Table4[[#This Row],[Vehicle no]],[1]Sheet2!$B:$J,4,0) -> MOHAMED BAKARI MSHIRAZI | C73: =VLOOKUP(Table4[[#This Row],[Vehicle no]],[1]Sheet2!$B:$J,9,0) -> Martha GOLODI | D73: =VLOOKUP(Table4[[#This Row],[Vehicle no]],[1]Sheet2!$B:$J,8,0) -> 133-846-425 | E73: 46077.232 | F73: 2026-02-24 | G73: Doma | H73: 46077.441 | I73: Kibaha TC, Morogoro Main Road | J73: 5:01:20 | K73: 205.61 km | L73: Early start
A74: T947DSX | B74: =VLOOKUP(Table4[[#This Row],[Vehicle no]],[1]Sheet2!$B:$J,4,0) -> JEPHA ANDREW JORAM | C74: =VLOOKUP(Table4[[#This Row],[Vehicle no]],[1]Sheet2!$B:$J,9,0) -> Ayoub BENESTA | D74: =VLOOKUP(Table4[[#This Row],[Vehicle no]],[1]Sheet2!$B:$J,8,0) -> 115259709 | E74: 46077.234 | F74: 2026-02-24 | G74: Kikwaraza | H74: 46077.463 | I74: IPOGOLO IRINGA | J74: 5:29:08 | K74: 185.34 km | L74: Early start
A75: T986EBW | B75: =VLOOKUP(Table4[[#This Row],[Vehicle no]],[1]Sheet2!$B:$J,4,0) -> THADEUS CHARLES HONGOLI | C75: =VLOOKUP(Table4[[#This Row],[Vehicle no]],[1]Sheet2!$B:$J,9,0) -> IRENE SHIJA | D75: =VLOOKUP(Table4[[#This Row],[Vehicle no]],[1]Sheet2!$B:$J,8,0) -> #N/A | E75: 46077.228 | F75: 2026-02-24 | G75: IGURUSI | H75: 46077.359 | I75: MAKAMBAKO | J75: 3:08:12 | K75: 119.26 km | L75: Early start
A76: T269EBX | B76: =VLOOKUP(Table4[[#This Row],[Vehicle no]],[1]Sheet2!$B:$J,4,0) -> MOHAMEDI IDDI KULWA | C76: =VLOOKUP(Table4[[#This Row],[Vehicle no]],[1]Sheet2!$B:$J,9,0) -> LUSAJO KASUNGA | D76: =VLOOKUP(Table4[[#This Row],[Vehicle no]],[1]Sheet2!$B:$J,8,0) -> #N/A | E76: 46078.236 | F76: 2026-02-25 | G76: Kidoma | H76: 46078.489 | I76: Mafinga TC, Tanzania to Zambia Road | J76: 6:04:13 | K76: 253.07 km | L76: Early start
A77: T404DHG | B77: =VLOOKUP(Table4[[#This Row],[Vehicle no]],[1]Sheet2!$B:$J,4,0) -> MWALIMU OMARY KIANGA | C77: =VLOOKUP(Table4[[#This Row],[Vehicle no]],[1]Sheet2!$B:$J,9,0) -> SADI KIMWAGA | D77: =VLOOKUP(Table4[[#This Row],[Vehicle no]],[1]Sheet2!$B:$J,8,0) -> 124-306-531 | E77: 46078.964 | F77: 2026-02-25 | G77: Pingo | H77: 46078.998 | I77: Pera | J77: 0:32:27 | K77: 11.80 km | L77: Night driving
A78: T749DEB | B78: =VLOOKUP(Table4[[#This Row],[Vehicle no]],[1]Sheet2!$B:$J,4,0) -> N/A | C78: =VLOOKUP(Table4[[#This Row],[Vehicle no]],[1]Sheet2!$B:$J,9,0) -> SADI KIMWAGA | D78: =VLOOKUP(Table4[[#This Row],[Vehicle no]],[1]Sheet2!$B:$J,8,0) -> #N/A | E78: 46078.97 | F78: 2026-02-25 | G78: Rn39, 5.52 km from Kisenda | H78: 46079 | I78: Rn39, 5.77 km from Kazembe | J78: 0:42:28 | K78: 7.63 km | L78: Night driving
A79: T986EBW | B79: =VLOOKUP(Table4[[#This Row],[Vehicle no]],[1]Sheet2!$B:$J,4,0) -> THADEUS CHARLES HONGOLI | C79: =VLOOKUP(Table4[[#This Row],[Vehicle no]],[1]Sheet2!$B:$J,9,0) -> IRENE SHIJA | D79: =VLOOKUP(Table4[[#This Row],[Vehicle no]],[1]Sheet2!$B:$J,8,0) -> #N/A | E79: 46078.229 | F79: 2026-02-25 | G79: Kikwaraza | H79: 46078.401 | I79: Bwawani | J79: 4:07:40 | K79: 164.73 km | L79: Early start
A80: T146EBX | B80: =VLOOKUP(Table4[[#This Row],[Vehicle no]],[1]Sheet2!$B:$J,4,0) -> HASSAN ABDALLAH JUMA | C80: =VLOOKUP(Table4[[#This Row],[Vehicle no]],[1]Sheet2!$B:$J,9,0) -> Ayoub BENESTA | D80: =VLOOKUP(Table4[[#This Row],[Vehicle no]],[1]Sheet2!$B:$J,8,0) -> 115-774-107 | E80: 46079.215 | F80: 2026-02-26 | G80: Kisarawe, R708 | H80: 46079.323 | I80: DAR ES SALAAM | J80: 2:30:29 | K80: 61.35 km | L80: Early start
...

Sheet OFFENSE
A1: Offense
A2: Night driving
A3: Driving Without Convoy Day
A4: Driving Without Convoy Night
A5: Early start

Sheet IDLING OPERATIONAL SUMMARY
A1: IDLING OPERATIONAL DELAY CLASSIFICATION SUMMARY
A2: OVERALL VIOLATIONS REPORT 01.03.2026.xlsx
A3: Total idling records | B3: 1160
A4: Total NO OF EVENTS | B4: 4292
A6: Category Summary (event-weighted)
A7: Category | B7: Records | C7: Records % | D7: NO OF EVENTS | E7: Events % | F7: Interpretation
A8: Stuck in traffic jam / checkpoint area | B8: 670 | C8: 0.57758621 | D8: 2494 | E8: 0.58108108 | F8: Likely operational delay
A9: Unclassified / needs review | B9: 257 | C9: 0.22155172 | D9: 894 | E9: 0.2082945 | F9: Needs manual review
A10: At border clearance | B10: 106 | C10: 0.09137931 | D10: 457 | E10: 0.10647717 | F10: Likely operational delay
A11: Waiting at loading / offloading | B11: 108 | C11: 0.093103448 | D11: 381 | E11: 0.088769804 | F11: Likely operational delay
A12: Waiting at weighbridge | B12: 19 | C12: 0.01637931 | D12: 66 | E12: 0.015377446 | F12: Likely operational delay
A14: Operational delay (sum of 5 categories) | B14: 903 | C14: 0.77844828 | D14: 3398 | E14: 0.7917055
A15: Not operational delay (Needs review) | B15: 257 | C15: 0.22155172 | D15: 894 | E15: 0.2082945
A17: Top Idling Hotspots by NO OF EVENTS (evidence)
A18: Location | B18: Category | C18: Records | D18: NO OF EVENTS | E18: Events %
A19: Kisarawe, R708 | B19: Waiting at loading / offloading | C19: 50 | D19: 176 | E19: 0.041006524
A20: Rn1, Kasumbalesa | B20: At border clearance | C20: 31 | D20: 166 | E20: 0.038676608
A21: Great North Road, Serenje | B21: Stuck in traffic jam / checkpoint area | C21: 30 | D21: 96 | E21: 0.022367195
A22: T1, Kongolo Mkola | B22: Stuck in traffic jam / checkpoint area | C22: 18 | D22: 76 | E22: 0.017707363
A23: T1, Makwenje | B23: Unclassified / needs review | C23: 19 | D23: 64 | E23: 0.014911463
A24: Ndola - Kitwe Dual-Carriageway, 33.24 km from Ndola | B24: Stuck in traffic jam / checkpoint area | C24: 14 | D24: 56 | E24: 0.01304753
A25: Iringa Road, Ruaha Mbuyumi | B25: Unclassified / needs review | C25: 16 | D25: 56 | E25: 0.01304753
A26: Ndola - Kitwe Dual-Carriageway, 33.18 km from Ndola | B26: Stuck in traffic jam / checkpoint area | C26: 15 | D26: 55 | E26: 0.012814539
A27: T1, Bwawani | B27: Stuck in traffic jam / checkpoint area | C27: 17 | D27: 54 | E27: 0.012581547
A28: Route De La Mine Deziwa, 5.76 km from Kisenda | B28: Waiting at loading / offloading | C28: 14 | D28: 53 | E28: 0.012348555
A29: T1, Igawa | B29: Stuck in traffic jam / checkpoint area | C29: 13 | D29: 50 | E29: 0.011649581
A30: Lundamatwe, Iringa Road | B30: Stuck in traffic jam / checkpoint area | C30: 14 | D30: 45 | E30: 0.010484623
... A58: Rn1, Sumbilili | B58: Stuck in traffic jam / checkpoint area | C58: 5 | D58: 16 | E58: 0.0037278658

Sheet IDLING CLASSIFIED DETAIL
A1: SN | B1: TRUCK NO | C1: RPT_DT | D1: Location | E1: Same-day trucks in area | F1: Same-day area events | G1: Category | H1: NO OF EVENTS
A2: 1 | B2: T129EBX | C2: 2026-02-01 | D2: T1, Mbalamaziwa | E2: 1 | F2: 3 | G2: Unclassified / needs review | H2: 3
A3: 2 | B3: T150EBX | C3: 2026-02-01 | D3: Rn1, 26.71 km from Lubumbashi | E3: 2 | F3: 6 | G3: Unclassified / needs review | H3: 3
A4: 3 | B4: T166EBX | C4: 2026-02-01 | D4: T1, Kongolo Mkola | E4: 1 | F4: 5 | G4: Unclassified / needs review | H4: 5
A5: 4 | B5: T172EBX | C5: 2026-02-01 | D5: Regional Hospital Road, 2.41 km from Mbeya | E5: 2 | F5: 6 | G5: At border clearance | H5: 3
A6: 5 | B6: T220EBX | C6: 2026-02-01 | D6: Rn1, 3.69 km from Kasumbalesa | E6: 4 | F6: 12 | G6: At border clearance | H6: 3
A7: 6 | B7: T227EBX | C7: 2026-02-01 | D7: Ndola, Fisenge Bypass | E7: 3 | F7: 16 | G7: Stuck in traffic jam / checkpoint area | H7: 3
A8: 7 | B8: T250EBX | C8: 2026-02-01 | D8: T1, 8.00 km from Ivugula | E8: 3 | F8: 9 | G8: Stuck in traffic jam / checkpoint area | H8: 3
A9: 8 | B9: T263DDJ | C9: 2026-02-01 | D9: Lundamatwe, Iringa Road | E9: 2 | F9: 7 | G9: Unclassified / needs review | H9: 3
A10: 9 | B10: T267DDJ | C10: 2026-02-01 | D10: Ndola - Kitwe Dual-Carriageway, 33.24 km from Ndola | E10: 5 | F10: 24 | G10: Stuck in traffic jam / checkpoint area | H10: 7
A11: 10 | B11: T301EBX | C11: 2026-02-01 | D11: Rn1, 26.96 km from Lubumbashi | E11: 2 | F11: 6 | G11: Unclassified / needs review | H11: 3
A12: 11 | B12: T314DDJ | C12: 2026-02-01 | D12: Great North Road, Serenje | E12: 3 | F12: 10 | G12: Stuck in traffic jam / checkpoint area | H12: 3
A13: 12 | B13: T325ECN | C13: 2026-02-01 | D13: T3, 10.04 km from Chingola | E13: 6 | F13: 29 | G13: Stuck in traffic jam / checkpoint area | H13: 5
... A1161: 1160 | B1161: T941EBW | C1161: 2026-02-28 | D1161: Rn1, 2.48 km from Kaidi | E1161: 12 | F1161: 46 | G1161: Stuck in traffic jam / checkpoint area | H1161: 4
