Workbook

Sheet OVERALL SUMMARY 
B2: DAYS | C2: Night driving | D2: Early start | E2: Driving Without Convoy Night | F2: Driving Without Convoy Day | G2: Exceeded idle | H2: HARSH BRAKE | I2: Over Speeding
B3: JANUARY MONTH 2026 | C3: =COUNTIF('NIGHT DRIVING REPORT '!L:L,C2) -> 36 | D3: =COUNTIF('NIGHT DRIVING REPORT '!L:L,D2) -> 106 | E3: =COUNTIF('NIGHT DRIVING REPORT '!L:L,E2) -> 0 | F3: =COUNTIF('NIGHT DRIVING REPORT '!L:L,'NIGHT DRIVING REPORT '!#REF!) -> 0 | G3: =SUM('IDLING VOLATION'!H:H) -> 918 | H3: =SUM('HARSH BRAKE VIOLATION'!H:H) -> 536 | I3: =SUM(' OVER SPEEDING VIOLATION '!I:I) -> 290
B4: 46030 | C4: 0 | D4: 6 | E4: 0 | F4: 0 | G4: 74 | H4: 88 | I4: 22

Sheet FOR SHEQ
A1: RPT_DT | B1: 2026-01-09 | D1: RPT_DT | E1: 2026-01-09 | G1: RPT_DT | H1: 08.01.2026 | J1: RPT_DT | K1: 2026-01-08
A2: IDLING VOLATION | D2: HARSH BRAKE VIOLATION | G2: OVER SPEEDING VIOLATION | J2: NIGHT DRIVING REPORT
A3: Row Labels | B3: Sum of NO OF EVENTS | D3: TRUCK NO | E3: NO OF EVENTS | G3: Row Labels | H3: NO OF EVENTS | J3: Count of Offense | K3: Column Labels
A4: T960DSX | B4: 4 | D4: T175EBX | E4: 5 | G4: T728DYR | H4: 2 | J4: Row Labels | K4: Early start | L4: Grand Total
A5: T728DYR | B5: 8 | D5: T873EBY | E5: 7 | G5: T518DEB | H5: 1 | J5: T774DYR | K5: 1 | L5: 1
A6: T703EBX | B6: 3 | D6: T720DYR | E6: 6 | G6: T337EBX | H6: 2 | J6: T287DDJ | K6: 1 | L6: 1
A7: T107EBX | B7: 3 | D7: T331EBX | E7: 3 | G7: T728EBX | H7: 5 | J7: T427DHG | K7: 1 | L7: 1
A8: T335ECN | B8: 5 | D8: T663DTQ | E8: 3 | G8: T444DHG | H8: 5 | J8: T711EBX | K8: 1 | L8: 1
A9: T796DYR | B9: 3 | D9: T907EBW | E9: 6 | G9: T571DYR | H9: 1 | J9: T796DYR | K9: 1 | L9: 1
A10: T676EBX | B10: 3 | D10: T796DYR | E10: 5 | G10: T905EBW | H10: 2 | J10: T954EBW | K10: 1 | L10: 1
A11: T873EBY | B11: 3 | D11: T873EBW | E11: 3 | G11: T263DDJ | H11: 2 | J11: Grand Total | K11: 6 | L11: 6
A12: T576DTQ | B12: 3 | D12: T732EBX | E12: 3 | G12: T732DEB | H12: 1
A13: T942DSX | B13: 3 | D13: T803EBW | E13: 3 | G13: T518EBY | H13: 1
A14: T955DSX | B14: 4 | D14: T871EBW | E14: 10 | G14: Grand Total | H14: 22
A15: T735EBX | B15: 3 | D15: T508EBY | E15: 4
A16: T816DDS | B16: 3 | D16: T812EBW | E16: 3
A17: T407DHE | B17: 5 | D17: T319EBY | E17: 5
A18: T342DHG | B18: 4 | D18: T521EBY | E18: 4
A19: T343EBX | B19: 3 | D19: Grand Total | E19: 70
A20: T154EBX | B20: 3
A21: T600DTQ | B21: 3
A22: T149EBX | B22: 3
A23: T579DTQ | B23: 5
A24: T781EBW | B24: 3
A25: T680EBX | B25: 3
A26: T907EBW | B26: 3
A27: T835EBY | B27: 4
A28: T528EBY | B28: 3
A29: T444DHG | B29: 4
A30: T416DHG | B30: 3
A31: T360DHG | B31: 4
... A34: Grand Total | B34: 109

Sheet IDLING VOLATION
A1: SN | B1: TRUCK NO | C1: Event time | D1: RPT_DT | E1: Time received | F1: Event text | G1: Location | H1: NO OF EVENTS
A2: 1 | B2: T930EBW | C2: 2026-01-01 06:56:42 | D2: =LEFT(C:C,10) -> 2026-01-01 | E2: 2026-01-01 07:26:43 | F2: T930EBW => IDLING. At 01.01.2026 06:56:42 it moved with speed 0 km/h near 'T2, Tanga, Handeni, Tanzania, 1.45 km from Ugweno'. | G2: T2, 1.45 km from Ugweno | H2: 4
A3: 2 | B3: T867EBY | C3: 2026-01-01 06:57:50 | D3: =LEFT(C:C,10) -> 2026-01-01 | E3: 2026-01-01 07:27:55 | F3: T867EBY => IDLING. At 01.01.2026 06:57:50 it moved with speed 0 km/h near 'T2, Tanga, Handeni, Tanzania, 1.43 km from Ugweno'. | G3: T2, 1.43 km from Ugweno | H3: 4
A4: 3 | B4: T439DHG | C4: 2026-01-01 07:36:20 | D4: =LEFT(C:C,10) -> 2026-01-01 | E4: 2026-01-01 08:06:20 | F4: T439DHG => IDLING. At 01.01.2026 07:36:20 it moved with speed 0 km/h near 'Great North Road, Muchinga Province, Zambia, 5.18 km from Two Leopards'. | G4: Great North Road, 5.18 km from Two Leopards | H4: 5
A5: 4 | B5: T378DHG | C5: 2026-01-01 07:51:55 | D5: =LEFT(C:C,10) -> 2026-01-01 | E5: 2026-01-01 08:21:59 | F5: T378DHG => IDLING. At 01.01.2026 07:51:55 it moved with speed 0 km/h near 'T3, Copperbelt Province, Zambia, 51.96 km from Ndola'. | G5: T3, 51.96 km from Ndola | H5: 3
A6: 5 | B6: T517EBY | C6: 2026-01-01 07:59:46 | D6: =LEFT(C:C,10) -> 2026-01-01 | E6: 2026-01-01 08:29:48 | F6: T517EBY => IDLING. At 01.01.2026 07:59:46 it moved with speed 0 km/h near 'Mbala - Nakonde Road, Muchinga Province, Zambia, 5.25 km from Mwezo'. | G6: Mbala - Nakonde Road, 5.25 km from Mwezo | H6: 4
A7: 6 | B7: T799DYR | C7: 2026-01-01 08:08:53 | D7: =LEFT(C:C,10) -> 2026-01-01 | E7: 2026-01-01 08:38:56 | F7: T799DYR => IDLING. At 01.01.2026 08:08:53 it moved with speed 0 km/h near 'Morogoro Main Road, Pwani, Kibaha, Tanzania, Mwendapole B'. | G7: Morogoro Main Road, Mwendapole B | H7: 3
A8: 7 | B8: T792EBW | C8: 2026-01-01 08:21:22 | D8: =LEFT(C:C,10) -> 2026-01-01 | E8: 2026-01-01 08:51:25 | F8: T792EBW => IDLING. At 01.01.2026 08:21:22 it moved with speed 0 km/h near 'Great North Road, Central Province, Zambia, 11.45 km from Kanona'. | G8: Great North Road, 11.45 km from Kanona | H8: 3
A9: 8 | B9: T737DEB | C9: 2026-01-01 08:31:35 | D9: =LEFT(C:C,10) -> 2026-01-01 | E9: 2026-01-01 09:01:38 | F9: T737DEB => IDLING. At 01.01.2026 08:31:35 it moved with speed 0 km/h near 'Rn1, Lualaba, Democratic Republic of the Congo, 2.56 km from Kaidi'. | G9: Rn1, 2.56 km from Kaidi | H9: 3
A10: 9 | B10: T514EBY | C10: 2026-01-01 08:44:44 | D10: =LEFT(C:C,10) -> 2026-01-01 | E10: 2026-01-01 09:14:45 | F10: T514EBY => IDLING. At 01.01.2026 08:44:44 it moved with speed 0 km/h near 'T1, Mbeya, Tanzania, Kongolo Mkola'. | G10: T1, Kongolo Mkola | H10: 4
A11: 10 | B11: T907EBW | C11: 2026-01-01 09:00:49 | D11: =LEFT(C:C,10) -> 2026-01-01 | E11: 2026-01-01 09:30:52 | F11: T907EBW => IDLING. At 01.01.2026 09:00:49 it moved with speed 0 km/h near 'Tanzam Road, Mbeya, Kalobe, Tanzania, 2.40 km from Mbeya'. | G11: Tanzam Road, 2.40 km from Mbeya | H11: 3
A12: 11 | B12: T934EBW | C12: 2026-01-01 09:16:10 | D12: =LEFT(C:C,10) -> 2026-01-01 | E12: 2026-01-01 09:46:13 | F12: T934EBW => IDLING. At 01.01.2026 09:16:10 it moved with speed 0 km/h near 'Great North Road, Muchinga Province, Zambia, Kalungu'. | G12: Great North Road, Kalungu | H12: 4
A13: 12 | B13: T799EBW | C13: 2026-01-01 09:36:51 | D13: =LEFT(C:C,10) -> 2026-01-01 | E13: 2026-01-01 10:06:54 | F13: T799EBW => IDLING. At 01.01.2026 09:36:51 it moved with speed 0 km/h near 'Regional Hospital Road, Mbeya, Nzovwe, Tanzania, 2.40 km from Mbeya'. | G13: Regional Hospital Road, 2.40 km from Mbeya | H13: 4
... A233: 232 | B233: T993EBW | C233: 2026-01-08 07:53:58 | D233: =LEFT(C:C,10) -> 2026-01-08 | E233: 2026-01-08 08:24:03 | F233: T993EBW => IDLING. At 08.01.2026 07:53:58 it moved with speed 0 km/h near 'T3, Copperbelt Province, Zambia, 4.69 km from Momba'. | G233: T3, 4.69 km from Momba | H233: 4
B234: T107EBX | C234: 2026-01-09 10:04:19 | D234: =LEFT(C:C,10) -> 2026-01-09 | E234: 2026-01-09 10:34:19 | F234: T107EBX => IDLING. At 09.01.2026 10:04:19 it moved with speed 0 km/h near 'T1, Njombe, Tanzania, 1.48 km from Nyololo'. | G234: T1, 1.48 km from Nyololo | H234: 3
B235: T149EBX | C235: 2026-01-09 06:47:51 | D235: =LEFT(C:C,10) -> 2026-01-09 | E235: 2026-01-09 07:17:55 | F235: T149EBX => IDLING. At 09.01.2026 06:47:51 it moved with speed 0 km/h near 'T1, Mbeya, Tanzania, Makwenje'. | G235: T1, Makwenje | H235: 3
B236: T154EBX | C236: 2026-01-09 12:16:41 | D236: =LEFT(C:C,10) -> 2026-01-09 | E236: 2026-01-09 12:46:43 | F236: T154EBX => IDLING. At 09.01.2026 12:16:41 it moved with speed 0 km/h near 'Iringa Road, Lundamatwe, Iringa, Tanzania'. | G236: Lundamatwe, Iringa Road | H236: 3
B237: T335ECN | C237: 2026-01-09 15:34:25 | D237: =LEFT(C:C,10) -> 2026-01-09 | E237: 2026-01-09 16:04:28 | F237: T335ECN => IDLING. At 09.01.2026 15:34:25 it moved with speed 0 km/h near 'Rue De La Kamoa Mine, Lualaba, Democratic Republic of the Congo, 26.77 km from Kapata'. | G237: Rue De La Kamoa Mine, 26.77 km from Kapata | H237: 5
B238: T342DHG | C238: 2026-01-09 08:32:08 | D238: =LEFT(C:C,10) -> 2026-01-09 | E238: 2026-01-09 09:02:11 | F238: T342DHG => IDLING. At 09.01.2026 08:32:08 it moved with speed 0 km/h near 'T1, Mbeya, Mbozi, Tanzania, Mlowo'. | G238: T1, Mlowo | H238: 4
B239: T343EBX | C239: 2026-01-09 09:35:49 | D239: =LEFT(C:C,10) -> 2026-01-09 | E239: 2026-01-09 10:05:49 | F239: T343EBX => IDLING. At 09.01.2026 09:35:49 it moved with speed 0 km/h near 'Tanzam Road, Mbeya, Mbozi, Tanzania, 1.60 km from Mbalizi'. | G239: Tanzam Road, 1.60 km from Mbalizi | H239: 3
B240: T360DHG | C240: 2026-01-09 07:56:50 | D240: =LEFT(C:C,10) -> 2026-01-09 | E240: 2026-01-09 08:26:52 | F240: T360DHG => IDLING. At 09.01.2026 07:56:50 it moved with speed 0 km/h near 'T3, Copperbelt Province, Zambia, 4.85 km from Momba'. | G240: T3, 4.85 km from Momba | H240: 4
B241: T407DHE | C241: 2026-01-09 15:36:59 | D241: =LEFT(C:C,10) -> 2026-01-09 | E241: 2026-01-09 16:07:03 | F241: T407DHE => IDLING. At 09.01.2026 15:36:59 it moved with speed 0 km/h near 'Rue De La Kamoa Mine, Lualaba, Democratic Republic of the Congo, 26.81 km from Kapata'. | G241: Rue De La Kamoa Mine, 26.81 km from Kapata | H241: 5
B242: T416DHG | C242: 2026-01-09 08:02:02 | D242: =LEFT(C:C,10) -> 2026-01-09 | E242: 2026-01-09 08:32:02 | F242: T416DHG => IDLING. At 09.01.2026 08:02:02 it moved with speed 0 km/h near 'Iringa Road, Morogoro, Kilosa, Tanzania, Kikwaraza'. | G242: Iringa Road, Kikwaraza | H242: 3
B243: T444DHG | C243: 2026-01-09 10:09:06 | D243: =LEFT(C:C,10) -> 2026-01-09 | E243: 2026-01-09 10:39:06 | F243: T444DHG => IDLING. At 09.01.2026 10:09:06 it moved with speed 0 km/h near 'Ndola - Kitwe Dual-Carriageway, Copperbelt Province, Zambia, 33.18 km from Ndola'. | G243: Ndola - Kitwe Dual-Carriageway, 33.18 km from Ndola | H243: 4
B244: T528EBY | C244: 2026-01-09 10:37:35 | D244: =LEFT(C:C,10) -> 2026-01-09 | E244: 2026-01-09 11:07:38 | F244: T528EBY => IDLING. At 09.01.2026 10:37:35 it moved with speed 0 km/h near 'Iringa Road, Morogoro, Tanzania, Doma'. | G244: Iringa Road, Doma | H244: 3
B245: T576DTQ | C245: 2026-01-09 12:52:00 | D245: =LEFT(C:C,10) -> 2026-01-09 | E245: 2026-01-09 13:22:00 | F245: T576DTQ => IDLING. At 09.01.2026 12:52:00 it moved with speed 0 km/h near 'T3, Central Province, Zambia, 6.95 km from Kapiri Mposhi'. | G245: T3, 6.95 km from Kapiri Mposhi | H245: 3
... B263: T960DSX | C263: 2026-01-09 10:14:14 | D263: =LEFT(C:C,10) -> 2026-01-09 | E263: 2026-01-09 10:44:16 | F263: T960DSX => IDLING. At 09.01.2026 10:14:14 it moved with speed 0 km/h near 'Ndola - Kitwe Dual-Carriageway, Copperbelt Province, Zambia, 33.22 km from Ndola'. | G263: Ndola - Kitwe Dual-Carriageway, 33.22 km from Ndola | H263: 4

Sheet HARSH BRAKE VIOLATION
A1: SN | B1: Row Labels | C1: Event time | D1: RPT_DT | E1: DRIVER NAME | F1: Event text | G1: Location | H1: Count of Time received
A2: 1 | B2: T728DYR | C2: 2026-01-01 05:58:42 | D2: =LEFT(Table2[[#This Row],[Event time]],10) -> 2026-01-01 | E2: =VLOOKUP(Table2[[#This Row],[Row Labels]],[1]Sheet2!$B:$J,4,0) -> ELIA JUMA NZOWA | F2: T728DYR: Harsh braking has been activated. At 01.01.2026 05:58:42 it moved with speed 75 km/h near 'Iringa Road, Iringa, Tanzania, Kware'. | G2: Iringa Road, Tanzania, Iringa, Kware | H2: 17
A3: 2 | B3: T334EBX | C3: 2026-01-01 06:06:27 | D3: =LEFT(Table2[[#This Row],[Event time]],10) -> 2026-01-01 | E3: =VLOOKUP(Table2[[#This Row],[Row Labels]],[1]Sheet2!$B:$J,4,0) -> ABDALLAH RASHID MBWANA | F3: T334EBX: Harsh braking has been activated. At 01.01.2026 06:06:27 it moved with speed 74 km/h near 'Tanzania To Zambia Road, Iringa, Mufindi, Tanzania, 1.81 km from Kinyanambo'. | G3: Tanzania To Zambia Road, Tanzania, Iringa, Mufindi, 1.81 km from Kinyanambo | H3: 7
A4: 3 | B4: T335EBX | C4: 2026-01-01 07:01:29 | D4: =LEFT(Table2[[#This Row],[Event time]],10) -> 2026-01-01 | E4: =VLOOKUP(Table2[[#This Row],[Row Labels]],[1]Sheet2!$B:$J,4,0) -> ALLY SAID MANDINGO | F4: T335EBX: Harsh braking has been activated. At 01.01.2026 07:01:29 it moved with speed 56 km/h near 'Great North Road, Muchinga Province, Zambia, 8.99 km from Mwezo'. | G4: Great North Road, Zambia, Muchinga Province, 8.99 km from Mwezo | H4: 3
A5: 4 | B5: T724DYR | C5: 2026-01-01 07:18:37 | D5: =LEFT(Table2[[#This Row],[Event time]],10) -> 2026-01-01 | E5: =VLOOKUP(Table2[[#This Row],[Row Labels]],[1]Sheet2!$B:$J,4,0) -> KHALIDY MOHAMEDY KIDOMO | F5: T724DYR: Harsh braking has been activated. At 01.01.2026 07:18:37 it moved with speed 61 km/h near 'T3, Copperbelt Province, Zambia, 9.45 km from Chingola'. | G5: T3, Zambia, Copperbelt Province, 9.45 km from Chingola | H5: 17
A6: 5 | B6: T869EBY | C6: 2026-01-01 07:47:22 | D6: =LEFT(Table2[[#This Row],[Event time]],10) -> 2026-01-01 | E6: =VLOOKUP(Table2[[#This Row],[Row Labels]],[1]Sheet2!$B:$J,4,0) -> RAFAEL ERASTO NZAWIBO | F6: T869EBY: Harsh braking has been activated. At 01.01.2026 07:47:22 it moved with speed 54 km/h near 'Great North Road, Central Province, Zambia, 12.79 km from Kanona'. | G6: Great North Road, Zambia, Central Province, 12.79 km from Kanona | H6: 3
A7: 6 | B7: T315EBX | C7: 2026-01-01 08:04:49 | D7: =LEFT(Table2[[#This Row],[Event time]],10) -> 2026-01-01 | E7: =VLOOKUP(Table2[[#This Row],[Row Labels]],[1]Sheet2!$B:$J,4,0) -> MOHAMED SAID HAKUNGWA | F7: T315EBX: Harsh braking has been activated. At 01.01.2026 08:04:49 it moved with speed 59 km/h near 'Great North Road, Muchinga Province, Zambia, 8.98 km from Kalungu'. | G7: Great North Road, Zambia, Muchinga Province, 8.98 km from Kalungu | H7: 10
A8: 7 | B8: T712DYR | C8: 2026-01-01 08:30:20 | D8: =LEFT(Table2[[#This Row],[Event time]],10) -> 2026-01-01 | E8: =VLOOKUP(Table2[[#This Row],[Row Labels]],[1]Sheet2!$B:$J,4,0) -> RAJABU HUSSEIN AHMAD | F8: T712DYR: Harsh braking has been activated. At 01.01.2026 08:30:20 it moved with speed 66 km/h near 'Tanzania To Zambia Road, Iringa, Mufindi, Tanzania, Ihemi'. | G8: Tanzania To Zambia Road, Tanzania, Iringa, Mufindi, Ihemi | H8: 4
A9: 8 | B9: T510EBY | C9: 2026-01-01 09:07:34 | D9: =LEFT(Table2[[#This Row],[Event time]],10) -> 2026-01-01 | E9: =VLOOKUP(Table2[[#This Row],[Row Labels]],[1]Sheet2!$B:$J,4,0) -> RASHIDI MUSTAFA ABDALLAH | F9: T510EBY: Harsh braking has been activated. At 01.01.2026 09:07:34 it moved with speed 69 km/h near 'Iringa Road, Iringa, Tanzania, 6.37 km from Mahenge'. | G9: Iringa Road, Tanzania, Iringa, 6.37 km from Mahenge | H9: 5
A10: 9 | B10: T710EBX | C10: 2026-01-01 09:31:19 | D10: =LEFT(Table2[[#This Row],[Event time]],10) -> 2026-01-01 | E10: =VLOOKUP(Table2[[#This Row],[Row Labels]],[1]Sheet2!$B:$J,4,0) -> MUMBA YASSINI KHAMISI | F10: T710EBX: Harsh braking has been activated. At 01.01.2026 09:31:19 it moved with speed 56 km/h near 'T2, Pwani, Bagamoyo, Tanzania, 5.05 km from Mandera'. | G10: T2, Tanzania, Pwani, Bagamoyo, 5.05 km from Mandera | H10: 3
A11: 10 | B11: T792EBW | C11: 2026-01-01 09:45:52 | D11: =LEFT(Table2[[#This Row],[Event time]],10) -> 2026-01-01 | E11: =VLOOKUP(Table2[[#This Row],[Row Labels]],[1]Sheet2!$B:$J,4,0) -> ALLY ISSA OMARY | F11: T792EBW: Harsh braking has been activated. At 01.01.2026 09:45:52 it moved with speed 53 km/h near 'Great North Road, Muchinga Province, Zambia, 10.40 km from Godfrey Kunda'. | G11: Great North Road, Zambia, Muchinga Province, 10.40 km from Godfrey Kunda | H11: 3
A12: 11 | B12: T585DYR | C12: 2026-01-01 09:56:22 | D12: =LEFT(Table2[[#This Row],[Event time]],10) -> 2026-01-01 | E12: =VLOOKUP(Table2[[#This Row],[Row Labels]],[1]Sheet2!$B:$J,4,0) -> RICHARD JOHN MWASILE | F12: T585DYR: Harsh braking has been activated. At 01.01.2026 09:56:22 it moved with speed 51 km/h near 'Great North Road, Central Province, Zambia, 2.04 km from Kanona'. | G12: Great North Road, Zambia, Central Province, 2.04 km from Kanona | H12: 9
A13: 12 | B13: T314DDJ | C13: 2026-01-01 11:35:08 | D13: =LEFT(Table2[[#This Row],[Event time]],10) -> 2026-01-01 | E13: =VLOOKUP(Table2[[#This Row],[Row Labels]],[1]Sheet2!$B:$J,4,0) -> HAMADI MOHAMED KACHEM | F13: T314DDJ: Harsh braking has been activated. At 01.01.2026 11:35:08 it moved with speed 71 km/h near 'Great North Road, Muchinga Province, Zambia, 2.17 km from Musata'. | G13: Great North Road, Zambia, Muchinga Province, 2.17 km from Musata | H13: 4
... A80: 79 | B80: T954EBW | C80: 2026-01-08 11:10:26 | D80: =LEFT(Table2[[#This Row],[Event time]],10) -> 2026-01-08 | E80: =VLOOKUP(Table2[[#This Row],[Row Labels]],[1]Sheet2!$B:$J,4,0) -> MOSES ELIBARIKI MSHANA | F80: T954EBW: Harsh braking has been activated. At 08.01.2026 11:10:26 it moved with speed 55 km/h near 'T1, Njombe, Tanzania, Idofi'. | G80: T1, Tanzania, Njombe, Idofi | H80: 3
B81: T175EBX | C81: 2026-01-09 09:12:16 | D81: =LEFT(Table2[[#This Row],[Event time]],10) -> 2026-01-09 | E81: =VLOOKUP(Table2[[#This Row],[Row Labels]],[1]Sheet2!$B:$J,4,0) -> ALLY JUMA ATHUMANI | F81: T175EBX: Harsh braking has been activated. At 09.01.2026 09:12:16 it moved with speed 68 km/h near 'Iringa Road, Morogoro, Kilosa, Tanzania, 13.69 km from Maharaka'. | G81: Iringa Road, Tanzania, Morogoro, Kilosa, 13.69 km from Maharaka | H81: 5
B82: T319EBY | C82: 2026-01-09 08:26:10 | D82: =LEFT(Table2[[#This Row],[Event time]],10) -> 2026-01-09 | E82: =VLOOKUP(Table2[[#This Row],[Row Labels]],[1]Sheet2!$B:$J,4,0) -> BAKARI MOHAMED SAID | F82: T319EBY: Harsh braking has been activated. At 09.01.2026 08:26:10 it moved with speed 62 km/h near 'Great North Road, Muchinga Province, Zambia, 9.02 km from Musata'. | G82: Great North Road, Zambia, Muchinga Province, 9.02 km from Musata | H82: 5
B83: T331EBX | C83: 2026-01-09 08:58:57 | D83: =LEFT(Table2[[#This Row],[Event time]],10) -> 2026-01-09 | E83: =VLOOKUP(Table2[[#This Row],[Row Labels]],[1]Sheet2!$B:$J,4,0) -> YUSUFU SAMSON NICODEMUS | F83: T331EBX: Harsh braking has been activated. At 09.01.2026 08:58:57 it moved with speed 51 km/h near 'T3, Copperbelt Province, Zambia, 3.27 km from Pukota'. | G83: T3, Zambia, Copperbelt Province, 3.27 km from Pukota | H83: 3
B84: T508EBY | C84: 2026-01-09 12:57:36 | D84: =LEFT(Table2[[#This Row],[Event time]],10) -> 2026-01-09 | E84: =VLOOKUP(Table2[[#This Row],[Row Labels]],[1]Sheet2!$B:$J,4,0) -> JOSEPH WILLIAM NTANDU | F84: T508EBY: Harsh braking has been activated. At 09.01.2026 12:57:36 it moved with speed 51 km/h near 'Rn1, Haut-Katanga, Democratic Republic of the Congo, 44.23 km from Lubumbashi'. | G84: Rn1, Democratic Republic of the Congo, Haut-Katanga, 44.23 km from Lubumbashi | H84: 4
B85: T521EBY | C85: 2026-01-09 07:06:30 | D85: =LEFT(Table2[[#This Row],[Event time]],10) -> 2026-01-09 | E85: =VLOOKUP(Table2[[#This Row],[Row Labels]],[1]Sheet2!$B:$J,4,0) -> SAID SALUM MOHAMED | F85: T521EBY: Harsh braking has been activated. At 09.01.2026 07:06:30 it moved with speed 53 km/h near 'Great North Road, Muchinga Province, Zambia, 10.36 km from Godfrey Kunda'. | G85: Great North Road, Zambia, Muchinga Province, 10.36 km from Godfrey Kunda | H85: 4
B86: T663DTQ | C86: 2026-01-09 15:58:55 | D86: =LEFT(Table2[[#This Row],[Event time]],10) -> 2026-01-09 | E86: =VLOOKUP(Table2[[#This Row],[Row Labels]],[1]Sheet2!$B:$J,4,0) -> ALLY HAMISI MPEMBA | F86: T663DTQ: Harsh braking has been activated. At 09.01.2026 15:58:55 it moved with speed 65 km/h near 'T1, Morogoro, Tanzania, 2.77 km from Bwawani'. | G86: T1, Tanzania, Morogoro, 2.77 km from Bwawani | H86: 3
B87: T720DYR | C87: 2026-01-09 10:47:58 | D87: =LEFT(Table2[[#This Row],[Event time]],10) -> 2026-01-09 | E87: =VLOOKUP(Table2[[#This Row],[Row Labels]],[1]Sheet2!$B:$J,4,0) -> STANLEY SAIMON MLOGANZALA | F87: T720DYR: Harsh braking has been activated. At 09.01.2026 10:47:58 it moved with speed 66 km/h near 'Great North Road, Muchinga Province, Zambia, 10.65 km from Chinunda'. | G87: Great North Road, Zambia, Muchinga Province, 10.65 km from Chinunda | H87: 6
B88: T732EBX | C88: 2026-01-09 08:13:30 | D88: =LEFT(Table2[[#This Row],[Event time]],10) -> 2026-01-09 | E88: =VLOOKUP(Table2[[#This Row],[Row Labels]],[1]Sheet2!$B:$J,4,0) -> KELNALDO MATHIS JUMA | F88: T732EBX: Harsh braking has been activated. At 09.01.2026 08:13:30 it moved with speed 59 km/h near 'T3, Copperbelt Province, Zambia, 53.11 km from Ndola'. | G88: T3, Zambia, Copperbelt Province, 53.11 km from Ndola | H88: 3
B89: T796DYR | C89: 2026-01-09 06:33:23 | D89: =LEFT(Table2[[#This Row],[Event time]],10) -> 2026-01-09 | E89: =VLOOKUP(Table2[[#This Row],[Row Labels]],[1]Sheet2!$B:$J,4,0) -> LEONIDAS KALUMUNA KAGENYI | F89: T796DYR: Harsh braking has been activated. At 09.01.2026 06:33:23 it moved with speed 53 km/h near 'Iringa Road, Morogoro, Kilosa, Tanzania, 3.99 km from Tambuka Reli'. | G89: Iringa Road, Tanzania, Morogoro, Kilosa, 3.99 km from Tambuka Reli | H89: 5
B90: T803EBW | C90: 2026-01-09 11:29:20 | D90: =LEFT(Table2[[#This Row],[Event time]],10) -> 2026-01-09 | E90: =VLOOKUP(Table2[[#This Row],[Row Labels]],[1]Sheet2!$B:$J,4,0) -> JAPHARY NASSORO JAPHARY | F90: T803EBW: Harsh braking has been activated. At 09.01.2026 11:29:20 it moved with speed 57 km/h near 'Rn1, Haut-Katanga, Democratic Republic of the Congo, 4.56 km from Lwambo'. | G90: Rn1, Democratic Republic of the Congo, Haut-Katanga, 4.56 km from Lwambo | H90: 3
B91: T812EBW | C91: 2026-01-09 08:44:04 | D91: =LEFT(Table2[[#This Row],[Event time]],10) -> 2026-01-09 | E91: =VLOOKUP(Table2[[#This Row],[Row Labels]],[1]Sheet2!$B:$J,4,0) -> HASSAN RAMADHANI SHABANI | F91: T812EBW: Harsh braking has been activated. At 09.01.2026 08:44:04 it moved with speed 56 km/h near 'T1, Njombe, Tanzania, 2.36 km from Idofi'. | G91: T1, Tanzania, Njombe, 2.36 km from Idofi | H91: 3
B92: T871EBW | C92: 2026-01-09 12:38:17 | D92: =LEFT(Table2[[#This Row],[Event time]],10) -> 2026-01-09 | E92: =VLOOKUP(Table2[[#This Row],[Row Labels]],[1]Sheet2!$B:$J,4,0) -> IDRISA IBRAHIM SAID | F92: T871EBW: Harsh braking has been activated. At 09.01.2026 12:38:17 it moved with speed 61 km/h near 'Rn1, Haut-Katanga, Democratic Republic of the Congo, 21.03 km from Tumbwe'. | G92: Rn1, Democratic Republic of the Congo, Haut-Katanga, 21.03 km from Tumbwe | H92: 10
... B95: T907EBW | C95: 2026-01-09 06:59:00 | D95: =LEFT(Table2[[#This Row],[Event time]],10) -> 2026-01-09 | E95: =VLOOKUP(Table2[[#This Row],[Row Labels]],[1]Sheet2!$B:$J,4,0) -> ELIBAS EZEKIEL KITUNGWA | F95: T907EBW: Harsh braking has been activated. At 09.01.2026 06:59:00 it moved with speed 67 km/h near 'Great North Road, Central Province, Zambia, 5.36 km from Kapiri Mposhi'. | G95: Great North Road, Zambia, Central Province, 5.36 km from Kapiri Mposhi | H95: 6

Sheet  OVER SPEEDING VIOLATION 
A1: SN | B1: TRUCK NO | C1: Time | D1: RPT_DT | E1: DRIVER NAME | F1: MAX SPEED | G1: Location | H1: Speed limit | I1: Count
A2: 1 | B2: T994EBW | C2: 01.01.2026 04:11:56 pm | D2: =LEFT(Table1[[#This Row],[Time]],10) -> 01.01.2026 | E2: =VLOOKUP(Table1[[#This Row],[TRUCK NO ]],[1]Sheet2!$B:$E,4,0) -> SAIDI OMARI MTEA | F2: 88 | G2: Great North Road, Muchinga Province, Zambia, 8.58 km from Two Leopards | H2: 81 | I2: 5
A3: 2 | B3: T373DHG | C3: 01.01.2026 06:36:40 am | D3: =LEFT(Table1[[#This Row],[Time]],10) -> 01.01.2026 | E3: =VLOOKUP(Table1[[#This Row],[TRUCK NO ]],[1]Sheet2!$B:$E,4,0) -> ALPHONCE SIMO HORO | F3: 87 | G3: T1, Mbeya, Mbozi, Tanzania, 5.87 km from Idiga Songwe | H3: 81 | I3: 6
A4: 3 | B4: T334EBX | C4: 01.01.2026 07:12:22 am | D4: =LEFT(Table1[[#This Row],[Time]],10) -> 01.01.2026 | E4: =VLOOKUP(Table1[[#This Row],[TRUCK NO ]],[1]Sheet2!$B:$E,4,0) -> ABDALLAH RASHID MBWANA | F4: 92 | G4: Tanzania To Zambia Road, Iringa, Mufindi, Tanzania, 2.20 km from Ugwachanya | H4: 81 | I4: 2
A5: 4 | B5: T518DEB | C5: 01.01.2026 10:46:23 am | D5: =LEFT(Table1[[#This Row],[Time]],10) -> 01.01.2026 | E5: =VLOOKUP(Table1[[#This Row],[TRUCK NO ]],[1]Sheet2!$B:$E,4,0) -> 0 | F5: 89 | G5: DANGER ZONE BUNGU-BUNGU TO TUMBWE - THEFTS!!!!! | H5: 81 | I5: 1
A6: 5 | B6: T311EBX | C6: 02.01.2026 02:39:34 pm | D6: =LEFT(Table1[[#This Row],[Time]],10) -> 02.01.2026 | E6: =VLOOKUP(Table1[[#This Row],[TRUCK NO ]],[1]Sheet2!$B:$E,4,0) -> AMIRI AMANI MAWAKA | F6: 92 | G6: Route De Lubumbashi, Haut-Katanga, Democratic Republic of the Congo, Mbalaka | H6: 81 | I6: 13
A7: 6 | B7: T882EBW | C7: 02.01.2026 02:53:58 pm | D7: =LEFT(Table1[[#This Row],[Time]],10) -> 02.01.2026 | E7: =VLOOKUP(Table1[[#This Row],[TRUCK NO ]],[1]Sheet2!$B:$E,4,0) -> JUMA SHUKURU JUMA | F7: 86 | G7: Great North Road, Muchinga Province, Zambia, 20.01 km from Katibunga | H7: 81 | I7: 2
A8: 7 | B8: T732DEB | C8: 02.01.2026 03:31:29 pm | D8: =LEFT(Table1[[#This Row],[Time]],10) -> 02.01.2026 | E8: =VLOOKUP(Table1[[#This Row],[TRUCK NO ]],[1]Sheet2!$B:$E,4,0) -> AFFIF ISMAIL KIZENGA | F8: 99 | G8: M3, Luapula Province, Zambia, 8.49 km from Kalundu | H8: 81 | I8: 3
A9: 8 | B9: T332EBX | C9: 02.01.2026 04:28:47 pm | D9: =LEFT(Table1[[#This Row],[Time]],10) -> 02.01.2026 | E9: =VLOOKUP(Table1[[#This Row],[TRUCK NO ]],[1]Sheet2!$B:$E,4,0) -> MUZAMIRU SAIDI NAHODA | F9: 95 | G9: DANGER ZONE BUNGU-BUNGU TO TUMBWE - THEFTS!!!!! | H9: 81 | I9: 7
A10: 9 | B10: T724DYR | C10: 02.01.2026 05:12:11 pm | D10: =LEFT(Table1[[#This Row],[Time]],10) -> 02.01.2026 | E10: =VLOOKUP(Table1[[#This Row],[TRUCK NO ]],[1]Sheet2!$B:$E,4,0) -> KHALIDY MOHAMEDY KIDOMO | F10: 86 | G10: Great North Road, Muchinga Province, Zambia, Isoka | H10: 81 | I10: 1
A11: 10 | B11: T934EBW | C11: 02.01.2026 10:26:32 am | D11: =LEFT(Table1[[#This Row],[Time]],10) -> 02.01.2026 | E11: =VLOOKUP(Table1[[#This Row],[TRUCK NO ]],[1]Sheet2!$B:$E,4,0) -> ALLY MBARAKA ALLY | F11: 92 | G11: Great North Road, Muchinga Province, Zambia, 10.10 km from Chinunda | H11: 81 | I11: 3
A12: 11 | B12: T890EBW | C12: 02.01.2026 11:04:54 am | D12: =LEFT(Table1[[#This Row],[Time]],10) -> 02.01.2026 | E12: =VLOOKUP(Table1[[#This Row],[TRUCK NO ]],[1]Sheet2!$B:$E,4,0) -> TWAHIR RASHID MSAKA | F12: 99 | G12: Great North Road, Muchinga Province, Zambia, 16.34 km from Mukukwe | H12: 81 | I12: 29
A13: 12 | B13: T404DHG | C13: 03.01.2026 04:24:57 pm | D13: =LEFT(Table1[[#This Row],[Time]],10) -> 03.01.2026 | E13: =VLOOKUP(Table1[[#This Row],[TRUCK NO ]],[1]Sheet2!$B:$E,4,0) -> MWALIMU OMARY KIANGA | F13: 90 | G13: ISOKA, ZAMBIA | H13: 81 | I13: 6
... A20: 19 | B20: T957DSX | C20: 04.01.2026 06:11:18 am | D20: =LEFT(Table1[[#This Row],[Time]],10) -> 04.01.2026 | E20: =VLOOKUP(Table1[[#This Row],[TRUCK NO ]],[1]Sheet2!$B:$E,4,0) -> LUSEKELO JEREMIA MWAMBETE | F20: 100 | G20: Iringa Road, Morogoro, Tanzania, 3.58 km from Kipera | H20: 81 | I20: 10
A21: 20 | B21: T401DHT | C21: 05.01.2026 06:51:19 am | D21: 05.01.2026 | E21: =VLOOKUP(Table1[[#This Row],[TRUCK NO ]],[1]Sheet2!$B:$E,4,0) -> JOSEPHAT MARO KEBURE | F21: 86 km/h | G21: T1, Morogoro, Tanzania, 1.51 km from Maseyu | H21: 81 km/h | I21: 2
A22: 21 | B22: T404DHG | C22: 05.01.2026 19:27:29 pm | D22: 05.01.2026 | E22: =VLOOKUP(Table1[[#This Row],[TRUCK NO ]],[1]Sheet2!$B:$E,4,0) -> MWALIMU OMARY KIANGA | F22: 85 km/h | G22: Fisenge Bypass, Copperbelt Province, Zambia, 33.31 km from Ndola | H22: 81 km/h | I22: 3
A23: 22 | B23: T499DYR | C23: 05.01.2026 14:02:41 pm | D23: 05.01.2026 | E23: =VLOOKUP(Table1[[#This Row],[TRUCK NO ]],[1]Sheet2!$B:$E,4,0) -> ALLY RAMADHANI ZANDA | F23: 91 km/h | G23: Iringa Road, Morogoro, Kilosa, Tanzania, 15.33 km from Msimba | H23: 81 km/h | I23: 1
A24: 23 | B24: T515EBY | C24: 05.01.2026 19:20:48 pm | D24: 05.01.2026 | E24: =VLOOKUP(Table1[[#This Row],[TRUCK NO ]],[1]Sheet2!$B:$E,4,0) -> ALLY ADAM SAMSIMBAZI | F24: 89 km/h | G24: M3, Northern Province, Zambia, 13.28 km from Luwingu | H24: 81 km/h | I24: 1
A25: 24 | B25: T571DYR | C25: 05.01.2026 18:30:58 pm | D25: 05.01.2026 | E25: =VLOOKUP(Table1[[#This Row],[TRUCK NO ]],[1]Sheet2!$B:$E,4,0) -> BOAZ GILIAD FYITI | F25: 90 km/h | G25: M3, Luapula Province, Zambia, 9.19 km from Kalundu | H25: 81 km/h | I25: 1
A26: 25 | B26: T710EBX | C26: 05.01.2026 07:12:59 am | D26: 05.01.2026 | E26: =VLOOKUP(Table1[[#This Row],[TRUCK NO ]],[1]Sheet2!$B:$E,4,0) -> MUMBA YASSINI KHAMISI | F26: 86 km/h | G26: Iringa Road, Iringa, Tanzania, 1.71 km from Mahenge | H26: 81 km/h | I26: 1
A27: 26 | B27: T965EBW | C27: 05.01.2026 08:33:29 am | D27: 05.01.2026 | E27: =VLOOKUP(Table1[[#This Row],[TRUCK NO ]],[1]Sheet2!$B:$E,4,0) -> MOHAMUD ALLY MWABUDA | F27: 86 km/h | G27: T1, Mbeya, Tanzania, 3.57 km from Igawa | H27: 81 km/h | I27: 1
A28: 27 | B28: T994EBW | C28: 05.01.2026 14:34:35 pm | D28: 05.01.2026 | E28: =VLOOKUP(Table1[[#This Row],[TRUCK NO ]],[1]Sheet2!$B:$E,4,0) -> SAIDI OMARI MTEA | F28: 90 km/h | G28: T1, Mbeya, Tanzania, 6.54 km from Igawa | H28: 81 km/h | I28: 2
A29: 28 | B29: T342DHG | C29: 06.01.2026 10:13:47 am | D29: =LEFT(Table1[[#This Row],[Time]],10) -> 06.01.2026 | E29: =VLOOKUP(Table1[[#This Row],[TRUCK NO ]],[1]Sheet2!$B:$E,4,0) -> IDDY RAJAB IDDY | F29: 89 km/h | G29: Great North Road, Central Province, Zambia, 4.39 km from Manjolo | H29: 81 km/h | I29: 1
A30: 29 | B30: T436DHG | C30: 06.01.2026 08:19:21 am | D30: =LEFT(Table1[[#This Row],[Time]],10) -> 06.01.2026 | E30: =VLOOKUP(Table1[[#This Row],[TRUCK NO ]],[1]Sheet2!$B:$E,4,0) -> MUSIN KAOZY MTEBE | F30: 87 km/h | G30: Great North Road, Central Province, Zambia, 12.45 km from Chitiwa | H30: 81 km/h | I30: 6
A31: 30 | B31: T571DYR | C31: 06.01.2026 08:44:44 am | D31: =LEFT(Table1[[#This Row],[Time]],10) -> 06.01.2026 | E31: =VLOOKUP(Table1[[#This Row],[TRUCK NO ]],[1]Sheet2!$B:$E,4,0) -> BOAZ GILIAD FYITI | F31: 93 km/h | G31: M3, Northern Province, Zambia, Chiwembe | H31: 81 km/h | I31: 1
A32: 31 | B32: T684EBX | C32: 06.01.2026 13:47:27 pm | D32: =LEFT(Table1[[#This Row],[Time]],10) -> 06.01.2026 | E32: =VLOOKUP(Table1[[#This Row],[TRUCK NO ]],[1]Sheet2!$B:$E,4,0) -> RAJABU RASHIDI MALUPU | F32: 85 km/h | G32: DIOMU SPEED AREA, ZAMBIA | H32: 81 km/h | I32: 1
A33: 32 | B33: T728EBX | C33: 06.01.2026 08:16:31 am | D33: =LEFT(Table1[[#This Row],[Time]],10) -> 06.01.2026 | E33: =VLOOKUP(Table1[[#This Row],[TRUCK NO ]],[1]Sheet2!$B:$E,4,0) -> CHRISTIAN NKWELA MAPUNDA | F33: 93 km/h | G33: KITWE DANGER ZONE!!, ZAMBIA | H33: 81 km/h | I33: 14
A34: 33 | B34: T873EBY | C34: 06.01.2026 11:15:57 am | D34: =LEFT(Table1[[#This Row],[Time]],10) -> 06.01.2026 | E34: =VLOOKUP(Table1[[#This Row],[TRUCK NO ]],[1]Sheet2!$B:$E,4,0) -> STEPHANO ABINELI ULOMI | F34: 92 km/h | G34: T2, Pwani, Bagamoyo, Tanzania, Mboga | H34: 81 km/h | I34: 3
A35: 34 | B35: T178EBX | C35: 07.01.2026 10:44:06 am | D35: =LEFT(Table1[[#This Row],[Time]],10) -> 07.01.2026 | E35: =VLOOKUP(Table1[[#This Row],[TRUCK NO ]],[1]Sheet2!$B:$E,4,0) -> MWAITA ALLY ISIHAKA | F35: 99 km/h | G35: KIBAMBA NEAR KIBAHA | H35: 81 | I35: 63
A36: 35 | B36: T263DDJ | C36: 07.01.2026 03:50:08 pm | D36: =LEFT(Table1[[#This Row],[Time]],10) -> 07.01.2026 | E36: =VLOOKUP(Table1[[#This Row],[TRUCK NO ]],[1]Sheet2!$B:$E,4,0) -> SAIMON GEORGE KAAYA | F36: 88 km/h | G36: Great North Road, Central Province, Zambia, 9.13 km from Serenje | H36: 81 | I36: 1
A37: 36 | B37: T337EBX | C37: 07.01.2026 07:51:55 am | D37: =LEFT(Table1[[#This Row],[Time]],10) -> 07.01.2026 | E37: =VLOOKUP(Table1[[#This Row],[TRUCK NO ]],[1]Sheet2!$B:$E,4,0) -> YAHYA HASSANI ADAM | F37: 92 km/h | G37: Great North Road, Muchinga Province, Zambia, 6.57 km from Mwezo | H37: 81 | I37: 1
A38: 37 | B38: T436DHG | C38: 07.01.2026 10:49:41 am | D38: =LEFT(Table1[[#This Row],[Time]],10) -> 07.01.2026 | E38: =VLOOKUP(Table1[[#This Row],[TRUCK NO ]],[1]Sheet2!$B:$E,4,0) -> MUSIN KAOZY MTEBE | F38: 92 km/h | G38: Great North Road, Muchinga Province, Zambia, 9.28 km from Two Leopards | H38: 81 | I38: 8
A39: 38 | B39: T518DEB | C39: 07.01.2026 04:48:51 pm | D39: =LEFT(Table1[[#This Row],[Time]],10) -> 07.01.2026 | E39: =VLOOKUP(Table1[[#This Row],[TRUCK NO ]],[1]Sheet2!$B:$E,4,0) -> 0 | F39: 92 km/h | G39: Great North Road, Muchinga Province, Zambia, 5.86 km from Rumbuka | H39: 81 | I39: 1
A40: 39 | B40: T684EBX | C40: 07.01.2026 12:51:47 pm | D40: =LEFT(Table1[[#This Row],[Time]],10) -> 07.01.2026 | E40: =VLOOKUP(Table1[[#This Row],[TRUCK NO ]],[1]Sheet2!$B:$E,4,0) -> RAJABU RASHIDI MALUPU | F40: 85 km/h | G40: Great North Road, Muchinga Province, Zambia, 19.30 km from Mukukwe | H40: 81 | I40: 1
A41: 40 | B41: T728EBX | C41: 07.01.2026 07:03:47 am | D41: =LEFT(Table1[[#This Row],[Time]],10) -> 07.01.2026 | E41: =VLOOKUP(Table1[[#This Row],[TRUCK NO ]],[1]Sheet2!$B:$E,4,0) -> CHRISTIAN NKWELA MAPUNDA | F41: 100 km/h | G41: Great North Road, Central Province, Zambia, 9.72 km from Serenje | H41: 81 | I41: 28
A42: 41 | B42: T822DDS | C42: 07.01.2026 06:50:13 pm | D42: =LEFT(Table1[[#This Row],[Time]],10) -> 07.01.2026 | E42: =VLOOKUP(Table1[[#This Row],[TRUCK NO ]],[1]Sheet2!$B:$E,4,0) -> JANUARY LAMECK AUGUSTINO | F42: 98 km/h | G42: ISOKA, ZAMBIA | H42: 81 | I42: 1
A43: 42 | B43: T960DSX | C43: 07.01.2026 07:06:47 am | D43: =LEFT(Table1[[#This Row],[Time]],10) -> 07.01.2026 | E43: =VLOOKUP(Table1[[#This Row],[TRUCK NO ]],[1]Sheet2!$B:$E,4,0) -> SWEDI SALEHE MAJORO | F43: 85 km/h | G43: Great North Road, Muchinga Province, Zambia, 9.49 km from Mwezo | H43: 81 | I43: 1
A44: 43 | B44: T263DDJ | C44: 08.01.2026 01:12:27 pm | D44: =LEFT(Table1[[#This Row],[Time]],10) -> 08.01.2026 | E44: =VLOOKUP(Table1[[#This Row],[TRUCK NO ]],[1]Sheet2!$B:$E,4,0) -> SAIMON GEORGE KAAYA | F44: 86 | G44: Great North Road, Muchinga Province, Zambia, 16.00 km from Mukwikile | H44: 81 | I44: 2
A45: 44 | B45: T337EBX | C45: 08.01.2026 07:17:09 am | D45: =LEFT(Table1[[#This Row],[Time]],10) -> 08.01.2026 | E45: =VLOOKUP(Table1[[#This Row],[TRUCK NO ]],[1]Sheet2!$B:$E,4,0) -> YAHYA HASSANI ADAM | F45: 85 | G45: CHILONGA ZAMBIA | H45: 81 | I45: 2
A46: 45 | B46: T444DHG | C46: 08.01.2026 01:36:18 pm | D46: =LEFT(Table1[[#This Row],[Time]],10) -> 08.01.2026 | E46: =VLOOKUP(Table1[[#This Row],[TRUCK NO ]],[1]Sheet2!$B:$E,4,0) -> NASIBU SAIDY GUBWE | F46: 98 | G46: SERENJE | H46: 81 | I46: 5
...

Sheet NIGHT DRIVING REPORT 
A1: Vehicle no | B1: Driver name | C1: TM NAME | D1: TC NAME | E1: Beginning | F1: RPT_DT | G1: Initial location | H1: End | I1: Final location | J1: DURATION | K1: Mileage | L1: Offense
A2: T232EBX | B2: =VLOOKUP(Table4[[#This Row],[Vehicle no]],[1]Sheet2!$B:$J,4,0) -> ELIAH YUSUPH MPANGO | C2: =VLOOKUP(Table4[[#This Row],[Vehicle no]],[1]Sheet2!$B:$J,9,0) -> IRENE SHIJA | E2: 2025-11-05 05:37:40 | F2: =LEFT(E:E,10) -> 2025-11-05 | G2: T1, Bwawani | H2: 2025-11-05 12:41:10 | I2: Lundamatwe, Iringa Road | J2: 7:03:30 | K2: 310.62363 | L2: Early start
A3: T180EBX | B3: =VLOOKUP(Table4[[#This Row],[Vehicle no]],[1]Sheet2!$B:$J,4,0) -> YUSUF ALLY MAWIMBI | C3: =VLOOKUP(Table4[[#This Row],[Vehicle no]],[1]Sheet2!$B:$J,9,0) -> IRENE SHIJA | E3: 2025-12-08 04:27:04 | F3: =LEFT(E:E,10) -> 2025-12-08 | G3: Iringa Road, Ruaha Mbuyumi | H3: 2025-12-08 08:03:45 | I3: Iringa Road, Kitu | J3: 3:36:41 | K3: 160.33632 | L3: Early start
A4: T256DDJ | B4: =VLOOKUP(Table4[[#This Row],[Vehicle no]],[1]Sheet2!$B:$J,4,0) -> ABDALLAH SAIDI RAMADHANI | C4: =VLOOKUP(Table4[[#This Row],[Vehicle no]],[1]Sheet2!$B:$J,9,0) -> LUSAJO KASUNGA | E4: 2025-12-08 04:55:27 | F4: =LEFT(E:E,10) -> 2025-12-08 | G4: IGUNGA | H4: 2025-12-08 23:01:20 | I4: Dar Es Salaam, Goba Road | J4: 4:49:11 | K4: 212.57806 | L4: Early start
A5: T683DEB | B5: =VLOOKUP(Table4[[#This Row],[Vehicle no]],[1]Sheet2!$B:$J,4,0) -> 0 | C5: =VLOOKUP(Table4[[#This Row],[Vehicle no]],[1]Sheet2!$B:$J,9,0) -> Martha GOLODI | D5: =VLOOKUP(Table4[[#This Row],[Vehicle no]],[1]Sheet2!$B:$J,8,0) -> 0 | E5: 2025-12-08 04:51:17 | F5: =LEFT(E:E,10) -> 2025-12-08 | G5: IGUNGA | H5: 2025-12-08 23:59:57 | I5: DAR ES SALAAM | J5: 9:54:16 | K5: 447.02779 | L5: Early start
A6: T690DHL | B6: =VLOOKUP(Table4[[#This Row],[Vehicle no]],[1]Sheet2!$B:$J,4,0) -> LOCAL | C6: =VLOOKUP(Table4[[#This Row],[Vehicle no]],[1]Sheet2!$B:$J,9,0) -> PLASDUS MAHUMBA | E6: 2025-12-08 05:07:01 | F6: =LEFT(E:E,10) -> 2025-12-08 | G6: Morogoro, Dar Es Salaam Road | H6: 2025-12-08 05:59:07 | I6: T1, Bwawani | J6: 0:52:06 | K6: 44.336285 | L6: Early start
A7: T934EBW | B7: =VLOOKUP(Table4[[#This Row],[Vehicle no]],[1]Sheet2!$B:$J,4,0) -> ALLY MBARAKA ALLY | C7: =VLOOKUP(Table4[[#This Row],[Vehicle no]],[1]Sheet2!$B:$J,9,0) -> Martha GOLODI | D7: =VLOOKUP(Table4[[#This Row],[Vehicle no]],[1]Sheet2!$B:$J,8,0) -> 112705767 | E7: 2025-12-08 04:27:57 | F7: =LEFT(E:E,10) -> 2025-12-08 | G7: Iringa Road, Ruaha Mbuyumi | H7: 2025-12-08 09:54:43 | I7: T1, Bwawani | J7: 5:26:46 | K7: 240.74493 | L7: Early start
A8: T104EBX | B8: =VLOOKUP(Table4[[#This Row],[Vehicle no]],[1]Sheet2!$B:$J,4,0) -> JOHN NICHOLAUS MASSAWE | C8: =VLOOKUP(Table4[[#This Row],[Vehicle no]],[1]Sheet2!$B:$J,9,0) -> IRENE SHIJA | E8: 2025-12-11 21:08:03 | F8: =LEFT(E:E,10) -> 2025-12-11 | G8: DANGER ZONE BUNGU-BUNGU TO TUMBWE - THEFTS!!!!! | H8: 2025-12-11 23:15:13 | I8: DANGER ZONE BUNGU-BUNGU TO TUMBWE - THEFTS!!!!! | J8: 0:58:08 | K8: 10.448693 | L8: Night driving
A9: T170EBX | B9: =VLOOKUP(Table4[[#This Row],[Vehicle no]],[1]Sheet2!$B:$J,4,0) -> JUMA ATHUMANI MTENGUKA | C9: =VLOOKUP(Table4[[#This Row],[Vehicle no]],[1]Sheet2!$B:$J,9,0) -> Ayoub BENESTA | D9: =VLOOKUP(Table4[[#This Row],[Vehicle no]],[1]Sheet2!$B:$J,8,0) -> 119402905 | E9: 2025-12-11 21:06:08 | F9: =LEFT(E:E,10) -> 2025-12-11 | G9: DANGER ZONE BUNGU-BUNGU TO TUMBWE - THEFTS!!!!! | H9: 2025-12-11 23:29:52 | I9: DANGER ZONE BUNGU-BUNGU TO TUMBWE - THEFTS!!!!! | J9: 1:10:17 | K9: 10.263168 | L9: Night driving
A10: T572DYR | B10: =VLOOKUP(Table4[[#This Row],[Vehicle no]],[1]Sheet2!$B:$J,4,0) -> ISMAIL KISANDU RUBASHA | C10: =VLOOKUP(Table4[[#This Row],[Vehicle no]],[1]Sheet2!$B:$J,9,0) -> SADI KIMWAGA | E10: 2025-12-11 04:34:16 | F10: =LEFT(E:E,10) -> 2025-12-11 | G10: MAKAMBAKO | H10: 2025-12-11 20:21:04 | I10: Morogoro Main Road, 1.53 km from Karabaka | J10: 5:42:25 | K10: 230.86238 | L10: Early start
A11: T861EBY | B11: =VLOOKUP(Table4[[#This Row],[Vehicle no]],[1]Sheet2!$B:$J,4,0) -> OMARY SAID MTAJI | C11: =VLOOKUP(Table4[[#This Row],[Vehicle no]],[1]Sheet2!$B:$J,9,0) -> SADI KIMWAGA | E11: 2025-12-11 21:10:24 | F11: =LEFT(E:E,10) -> 2025-12-11 | G11: DANGER ZONE BUNGU-BUNGU TO TUMBWE - THEFTS!!!!! | H11: 2025-12-11 23:22:30 | I11: DANGER ZONE BUNGU-BUNGU TO TUMBWE - THEFTS!!!!! | J11: 1:04:31 | K11: 10.672359 | L11: Night driving
A12: T891EBW | B12: =VLOOKUP(Table4[[#This Row],[Vehicle no]],[1]Sheet2!$B:$J,4,0) -> ISSA MOHAMED KIMWAGA | C12: =VLOOKUP(Table4[[#This Row],[Vehicle no]],[1]Sheet2!$B:$J,9,0) -> SADI KIMWAGA | D12: =VLOOKUP(Table4[[#This Row],[Vehicle no]],[1]Sheet2!$B:$J,8,0) -> 117-626-539 | E12: 2025-12-11 21:04:34 | F12: =LEFT(E:E,10) -> 2025-12-11 | G12: DANGER ZONE BUNGU-BUNGU TO TUMBWE - THEFTS!!!!! | H12: 2025-12-11 23:23:07 | I12: DANGER ZONE BUNGU-BUNGU TO TUMBWE - THEFTS!!!!! | J12: 1:12:04 | K12: 10.600411 | L12: Night driving
A13: T315EBX | B13: =VLOOKUP(Table4[[#This Row],[Vehicle no]],[1]Sheet2!$B:$J,4,0) -> MOHAMED SAID HAKUNGWA | C13: =VLOOKUP(Table4[[#This Row],[Vehicle no]],[1]Sheet2!$B:$J,9,0) -> IRENE SHIJA | D13: =VLOOKUP(Table4[[#This Row],[Vehicle no]],[1]Sheet2!$B:$J,8,0) -> 113-254-319 | E13: 2025-12-12 05:33:08 | F13: =LEFT(E:E,10) -> 2025-12-12 | G13: ILULA SOKONI | H13: 2025-12-12 07:07:52 | I13: Iringa Road, 1.43 km from Kware | J13: 1:34:44 | K13: 59.231285 | L13: Early start
A14: T336ECN | B14: =VLOOKUP(Table4[[#This Row],[Vehicle no]],[1]Sheet2!$B:$J,4,0) -> DIMALETI NELSON MWAMBIPILE | C14: =VLOOKUP(Table4[[#This Row],[Vehicle no]],[1]Sheet2!$B:$J,9,0) -> SADI KIMWAGA | E14: 2025-12-12 05:38:38 | F14: =LEFT(E:E,10) -> 2025-12-12 | G14: M1, 17.55 km from Gvh Mwantende | H14: 2025-12-12 20:06:32 | I14: M1, 5.30 km from Mzuzu | J14: 1:35:34 | K14: 35.146009 | L14: Early start
A15: T341EBX | B15: =VLOOKUP(Table4[[#This Row],[Vehicle no]],[1]Sheet2!$B:$J,4,0) -> JAMES JOSEPH NJAU | C15: =VLOOKUP(Table4[[#This Row],[Vehicle no]],[1]Sheet2!$B:$J,9,0) -> IRENE SHIJA | D15: =VLOOKUP(Table4[[#This Row],[Vehicle no]],[1]Sheet2!$B:$J,8,0) -> 118-477-685 | E15: 2025-12-12 05:41:08 | F15: =LEFT(E:E,10) -> 2025-12-12 | G15: Iringa Road, Ruaha Mbuyumi | H15: 2025-12-12 19:01:53 | I15: Regional Hospital Road, 2.42 km from Mbeya | J15: 10:23:22 | K15: 406.02941 | L15: Early start
A16: T575DYR | B16: =VLOOKUP(Table4[[#This Row],[Vehicle no]],[1]Sheet2!$B:$J,4,0) -> OMARY SEIF MGUBIRI | C16: =VLOOKUP(Table4[[#This Row],[Vehicle no]],[1]Sheet2!$B:$J,9,0) -> Ayoub BENESTA | D16: =VLOOKUP(Table4[[#This Row],[Vehicle no]],[1]Sheet2!$B:$J,8,0) -> 118-408-829 | E16: 2025-12-12 05:32:18 | F16: =LEFT(E:E,10) -> 2025-12-12 | G16: Iringa Road, Tambuka Reli | H16: 2025-12-12 07:38:48 | I16: Iringa Road, Ruaha Mbuyumi | J16: 1:52:40 | K16: 75.318943 | L16: Early start
A17: T688DEB | B17: =VLOOKUP(Table4[[#This Row],[Vehicle no]],[1]Sheet2!$B:$J,4,0) -> DENIS MUHAGAMA KAPINGA | C17: =VLOOKUP(Table4[[#This Row],[Vehicle no]],[1]Sheet2!$B:$J,9,0) -> SADI KIMWAGA | D17: =VLOOKUP(Table4[[#This Row],[Vehicle no]],[1]Sheet2!$B:$J,8,0) -> 116-325-268 | E17: 2025-12-12 05:21:31 | F17: =LEFT(E:E,10) -> 2025-12-12 | G17: DAR ES SALAAM | H17: 2025-12-12 07:12:32 | I17: Morogoro Main Road, 1.25 km from Karabaka | J17: 1:51:01 | K17: 54.516919 | L17: Early start
A18: T709EBX | B18: =VLOOKUP(Table4[[#This Row],[Vehicle no]],[1]Sheet2!$B:$J,4,0) -> GERVAS STEPHEN MWANGOSI | C18: =VLOOKUP(Table4[[#This Row],[Vehicle no]],[1]Sheet2!$B:$J,9,0) -> LUSAJO KASUNGA | E18: 2025-12-12 05:39:39 | F18: =LEFT(E:E,10) -> 2025-12-12 | G18: IFUNDA, IRINGA | H18: 2025-12-12 09:32:22 | I18: Iringa Road, Ruaha Mbuyumi | J18: 3:52:43 | K18: 146.88964 | L18: Early start
A19: T774EBW | B19: =VLOOKUP(Table4[[#This Row],[Vehicle no]],[1]Sheet2!$B:$J,4,0) -> MAKERE GACHUMA MAKERE | C19: =VLOOKUP(Table4[[#This Row],[Vehicle no]],[1]Sheet2!$B:$J,9,0) -> Martha GOLODI | D19: =VLOOKUP(Table4[[#This Row],[Vehicle no]],[1]Sheet2!$B:$J,8,0) -> 111992398 | E19: 2025-12-12 05:21:03 | F19: =LEFT(E:E,10) -> 2025-12-12 | G19: T1, 1.32 km from Igomelo | H19: 2025-12-12 21:54:04 | I19: Morogoro, Dar Es Salaam Road | J19: 8:28:06 | K19: 391.38639 | L19: Early start
A20: T142EBX | B20: =VLOOKUP(Table4[[#This Row],[Vehicle no]],[1]Sheet2!$B:$J,4,0) -> BRUNO WILLY MWAJILA | C20: =VLOOKUP(Table4[[#This Row],[Vehicle no]],[1]Sheet2!$B:$J,9,0) -> Martha GOLODI | D20: =VLOOKUP(Table4[[#This Row],[Vehicle no]],[1]Sheet2!$B:$J,8,0) -> 126-452-225 | E20: 2025-12-13 05:40:33 | F20: =LEFT(E:E,10) -> 2025-12-13 | G20: Iringa Road, Ruaha Mbuyumi | H20: 2025-12-13 07:17:36 | I20: Iringa Road, Mikumi | J20: 1:37:03 | K20: 74.12851 | L20: Early start
A21: T184EBX | B21: =VLOOKUP(Table4[[#This Row],[Vehicle no]],[1]Sheet2!$B:$J,4,0) -> MOHAMED MAKANDA MUHOGO | C21: =VLOOKUP(Table4[[#This Row],[Vehicle no]],[1]Sheet2!$B:$J,9,0) -> Ayoub BENESTA | D21: =VLOOKUP(Table4[[#This Row],[Vehicle no]],[1]Sheet2!$B:$J,8,0) -> 122904229 | E21: 2025-12-13 05:32:01 | F21: =LEFT(E:E,10) -> 2025-12-13 | G21: Iringa Road, Kikwaraza | H21: 2025-12-13 08:05:53 | I21: Morogoro, Dar Es Salaam Road | J21: 2:33:52 | K21: 121.42974 | L21: Early start
A22: T191EBX | B22: =VLOOKUP(Table4[[#This Row],[Vehicle no]],[1]Sheet2!$B:$J,4,0) -> ISAYA JOHN MSENA | C22: =VLOOKUP(Table4[[#This Row],[Vehicle no]],[1]Sheet2!$B:$J,9,0) -> IRENE SHIJA | D22: =VLOOKUP(Table4[[#This Row],[Vehicle no]],[1]Sheet2!$B:$J,8,0) -> 113485485 | E22: 2025-12-13 05:25:19 | F22: =LEFT(E:E,10) -> 2025-12-13 | G22: T1, Bwawani | H22: 2025-12-13 20:52:11 | I22: DAR ES SALAAM | J22: 1:59:22 | K22: 63.914397 | L22: Early start
A23: T271EBY | B23: =VLOOKUP(Table4[[#This Row],[Vehicle no]],[1]Sheet2!$B:$J,4,0) -> ISAYA MSHUKURU MMBANDO | C23: =VLOOKUP(Table4[[#This Row],[Vehicle no]],[1]Sheet2!$B:$J,9,0) -> LUSAJO KASUNGA | D23: =VLOOKUP(Table4[[#This Row],[Vehicle no]],[1]Sheet2!$B:$J,8,0) -> 124048907 | E23: 2025-12-13 04:47:28 | F23: =LEFT(E:E,10) -> 2025-12-13 | G23: Iringa Road, 1.26 km from Ruaha Mbuyumi | H23: 2025-12-13 21:05:43 | I23: DAR ES SALAAM | J23: 7:20:33 | K23: 250.11808 | L23: Early start
A24: T272EBX | B24: =VLOOKUP(Table4[[#This Row],[Vehicle no]],[1]Sheet2!$B:$J,4,0) -> POTPHA PASCAL MTAKIMWA | C24: =VLOOKUP(Table4[[#This Row],[Vehicle no]],[1]Sheet2!$B:$J,9,0) -> Ayoub BENESTA | D24: =VLOOKUP(Table4[[#This Row],[Vehicle no]],[1]Sheet2!$B:$J,8,0) -> 120-448-110 | E24: 2025-12-13 05:39:02 | F24: =LEFT(E:E,10) -> 2025-12-13 | G24: Tanzam Road, 2.52 km from Uyole | H24: 2025-12-13 08:28:00 | I24: T1, 2.44 km from Igando | J24: 2:48:58 | K24: 122.06547 | L24: Early start
A25: T326ECN | B25: =VLOOKUP(Table4[[#This Row],[Vehicle no]],[1]Sheet2!$B:$J,4,0) -> IBRAHIMU SELEMANI SENGAMBA | C25: =VLOOKUP(Table4[[#This Row],[Vehicle no]],[1]Sheet2!$B:$J,9,0) -> LUSAJO KASUNGA | E25: 2025-12-13 05:26:05 | F25: =LEFT(E:E,10) -> 2025-12-13 | G25: T1, Bwawani | H25: 2025-12-13 23:44:31 | I25: SALISLA | J25: 5:01:23 | K25: 142.63509 | L25: Early start
A26: T329ECN | B26: =VLOOKUP(Table4[[#This Row],[Vehicle no]],[1]Sheet2!$B:$J,4,0) -> JUMA KOBA SAID | C26: =VLOOKUP(Table4[[#This Row],[Vehicle no]],[1]Sheet2!$B:$J,9,0) -> LUSAJO KASUNGA | D26: =VLOOKUP(Table4[[#This Row],[Vehicle no]],[1]Sheet2!$B:$J,8,0) -> 120-026-526 | E26: 2025-12-13 05:37:04 | F26: =LEFT(E:E,10) -> 2025-12-13 | G26: Iringa Road, Ruaha Mbuyumi | H26: 2025-12-13 07:40:50 | I26: Iringa Road, Kikwaraza | J26: 2:03:46 | K26: 76.014949 | L26: Early start
A27: T725EBX | B27: =VLOOKUP(Table4[[#This Row],[Vehicle no]],[1]Sheet2!$B:$J,4,0) -> EZEKIEL MASANJA LUGANDU | C27: =VLOOKUP(Table4[[#This Row],[Vehicle no]],[1]Sheet2!$B:$J,9,0) -> PLASDUS MAHUMBA | E27: 2025-12-13 05:31:18 | F27: =LEFT(E:E,10) -> 2025-12-13 | G27: Iringa Road, Kikwaraza | H27: 2025-12-13 07:48:35 | I27: Morogoro, Iringa Road | J27: 2:17:17 | K27: 113.40689 | L27: Early start
A28: T727EBX | B28: =VLOOKUP(Table4[[#This Row],[Vehicle no]],[1]Sheet2!$B:$J,4,0) -> RAMADHANI SAID NCHIMBI | C28: =VLOOKUP(Table4[[#This Row],[Vehicle no]],[1]Sheet2!$B:$J,9,0) -> PLASDUS MAHUMBA | E28: 2025-12-13 05:34:59 | F28: =LEFT(E:E,10) -> 2025-12-13 | G28: Iringa Road, Ruaha Mbuyumi | H28: 2025-12-13 09:08:19 | I28: Iringa Road, 2.48 km from Mangaye | J28: 3:33:20 | K28: 146.6504 | L28: Early start
A29: T272EBX | B29: =VLOOKUP(Table4[[#This Row],[Vehicle no]],[1]Sheet2!$B:$J,4,0) -> POTPHA PASCAL MTAKIMWA | C29: =VLOOKUP(Table4[[#This Row],[Vehicle no]],[1]Sheet2!$B:$J,9,0) -> Ayoub BENESTA | D29: =VLOOKUP(Table4[[#This Row],[Vehicle no]],[1]Sheet2!$B:$J,8,0) -> 120-448-110 | E29: 2025-12-14 05:03:04 | F29: =LEFT(E:E,10) -> 2025-12-14 | G29: Iringa Road, 2.20 km from Ruaha Mbuyumi | H29: 2025-12-14 23:28:28 | I29: DAR ES SALAAM | J29: 4:20:04 | K29: 203.05127 | L29: Early start
A30: T376ECN | B30: =VLOOKUP(Table4[[#This Row],[Vehicle no]],[1]Sheet2!$B:$J,4,0) -> PETER BENJAMIN KINGU | C30: =VLOOKUP(Table4[[#This Row],[Vehicle no]],[1]Sheet2!$B:$J,9,0) -> Ayoub BENESTA | D30: =VLOOKUP(Table4[[#This Row],[Vehicle no]],[1]Sheet2!$B:$J,8,0) -> 113857625 | E30: 2025-12-14 05:39:29 | F30: =LEFT(E:E,10) -> 2025-12-14 | G30: T1, Mdaula | H30: 2025-12-14 23:34:22 | I30: IPOGOLO IRINGA | J30: 1:27:57 | K30: 43.931034 | L30: Early start
A31: T335EBX | B31: =VLOOKUP(Table4[[#This Row],[Vehicle no]],[1]Sheet2!$B:$J,4,0) -> ALLY SAID MANDINGO | C31: =VLOOKUP(Table4[[#This Row],[Vehicle no]],[1]Sheet2!$B:$J,9,0) -> LUSAJO KASUNGA | D31: =VLOOKUP(Table4[[#This Row],[Vehicle no]],[1]Sheet2!$B:$J,8,0) -> 115-904-280 | E31: 2025-12-15 05:40:46 | F31: =LEFT(E:E,10) -> 2025-12-15 | G31: IFUNDA, IRINGA | H31: 2025-12-15 11:13:05 | I31: Iringa Road, Kikwaraza | J31: 5:27:12 | K31: 222.41074 | L31: Early start
A32: T444DHG | B32: =VLOOKUP(Table4[[#This Row],[Vehicle no]],[1]Sheet2!$B:$J,4,0) -> NASIBU SAIDY GUBWE | C32: =VLOOKUP(Table4[[#This Row],[Vehicle no]],[1]Sheet2!$B:$J,9,0) -> LUSAJO KASUNGA | D32: =VLOOKUP(Table4[[#This Row],[Vehicle no]],[1]Sheet2!$B:$J,8,0) -> 144-695-674 | E32: 2025-12-15 05:28:19 | F32: =LEFT(E:E,10) -> 2025-12-15 | G32: Tanzania To Zambia Road, Mafinga | H32: 2025-12-15 06:54:14 | I32: Tanzania To Zambia Road, Tanangozi | J32: 1:25:55 | K32: 54.517227 | L32: Early start
A33: T838EBY | B33: =VLOOKUP(Table4[[#This Row],[Vehicle no]],[1]Sheet2!$B:$J,4,0) -> HAFIDHI ABDALLAH NASSIR | C33: =VLOOKUP(Table4[[#This Row],[Vehicle no]],[1]Sheet2!$B:$J,9,0) -> PLASDUS MAHUMBA | E33: 2025-12-15 05:39:27 | F33: =LEFT(E:E,10) -> 2025-12-15 | G33: Tanzania To Zambia Road, Changarawe | H33: 2025-12-15 07:13:23 | I33: Tanzania To Zambia Road, Tanangozi | J33: 1:33:56 | K33: 58.772667 | L33: Early start
A34: T939EBW | B34: =VLOOKUP(Table4[[#This Row],[Vehicle no]],[1]Sheet2!$B:$J,4,0) -> SEIF AMARY HAMAD | C34: =VLOOKUP(Table4[[#This Row],[Vehicle no]],[1]Sheet2!$B:$J,9,0) -> IRENE SHIJA | D34: =VLOOKUP(Table4[[#This Row],[Vehicle no]],[1]Sheet2!$B:$J,8,0) -> 121-656-582 | E34: 2025-12-15 05:32:48 | F34: =LEFT(E:E,10) -> 2025-12-15 | G34: IFUNDA, IRINGA | H34: 2025-12-15 19:14:21 | I34: T1, Mdaula | J34: 3:38:29 | K34: 147.39237 | L34: Early start
A35: T299DCT | B35: =VLOOKUP(Table4[[#This Row],[Vehicle no]],[1]Sheet2!$B:$J,4,0) -> AHMED SHAMSHU MOHAMED | C35: =VLOOKUP(Table4[[#This Row],[Vehicle no]],[1]Sheet2!$B:$J,9,0) -> Ayoub BENESTA | D35: =VLOOKUP(Table4[[#This Row],[Vehicle no]],[1]Sheet2!$B:$J,8,0) -> 116-005-034 | E35: 2025-12-15 20:57:52 | F35: =LEFT(E:E,10) -> 2025-12-15 | G35: Morogoro Main Road, 1.22 km from Karabaka | H35: 2025-12-15 23:59:42 | I35: Dar Es Salaam, Morogoro Main Road | J35: 0:47:52 | K35: 23.925776 | L35: Night driving
A36: T945DSX | B36: =VLOOKUP(Table4[[#This Row],[Vehicle no]],[1]Sheet2!$B:$J,4,0) -> SALUM KITENGE ALLY | C36: =VLOOKUP(Table4[[#This Row],[Vehicle no]],[1]Sheet2!$B:$J,9,0) -> SADI KIMWAGA | D36: =VLOOKUP(Table4[[#This Row],[Vehicle no]],[1]Sheet2!$B:$J,8,0) -> 114-626-732 | E36: 2025-12-15 20:47:41 | F36: =LEFT(E:E,10) -> 2025-12-15 | G36: GALCO ICD MBOZI | H36: 2025-12-15 23:41:53 | I36: Morogoro Main Road, 1.25 km from Karabaka | J36: 2:17:21 | K36: 60.929727 | L36: Night driving
A37: T266EBX | E37: 2025-12-16 05:24:24 | F37: =LEFT(E:E,10) -> 2025-12-16 | G37: T1, Bwawani | H37: 2025-12-16 06:50:55 | I37: T1, 4.29 km from Vigwaza | J37: 1:26:31 | K37: 62.275068 | L37: Early start
A38: T302EBX | B38: =VLOOKUP(Table4[[#This Row],[Vehicle no]],[1]Sheet2!$B:$J,4,0) -> MUSSA MASASI MRINDOKO | C38: =VLOOKUP(Table4[[#This Row],[Vehicle no]],[1]Sheet2!$B:$J,9,0) -> IRENE SHIJA | E38: 2025-12-16 05:49:15 | F38: =LEFT(E:E,10) -> 2025-12-16 | G38: Iringa Road, Melela Mlandizi | H38: 2025-12-16 08:54:33 | I38: T1, Msolwa | J38: 3:05:18 | K38: 118.03504 | L38: Early start
A39: T335EBX | B39: =VLOOKUP(Table4[[#This Row],[Vehicle no]],[1]Sheet2!$B:$J,4,0) -> ALLY SAID MANDINGO | C39: =VLOOKUP(Table4[[#This Row],[Vehicle no]],[1]Sheet2!$B:$J,9,0) -> LUSAJO KASUNGA | D39: =VLOOKUP(Table4[[#This Row],[Vehicle no]],[1]Sheet2!$B:$J,8,0) -> 115-904-280 | E39: 2025-12-16 05:24:33 | F39: =LEFT(E:E,10) -> 2025-12-16 | G39: T1, Bwawani | H39: 2025-12-16 07:46:29 | I39: Morogoro Main Road, 1.55 km from Karabaka | J39: 2:21:56 | K39: 93.449494 | L39: Early start
A40: T336ECN | B40: =VLOOKUP(Table4[[#This Row],[Vehicle no]],[1]Sheet2!$B:$J,4,0) -> DIMALETI NELSON MWAMBIPILE | C40: =VLOOKUP(Table4[[#This Row],[Vehicle no]],[1]Sheet2!$B:$J,9,0) -> SADI KIMWAGA | E40: 2025-12-16 05:45:34 | F40: =LEFT(E:E,10) -> 2025-12-16 | G40: Iringa Road, Mikumi | H40: 2025-12-16 18:59:46 | I40: DAR ES SALAAM | J40: 1:12:05 | K40: 53.338915 | L40: Early start
...

Sheet OFFENSE
A1: Offense
A2: Night driving
A3: Driving Without Convoy Day
A4: Driving Without Convoy Night
A5: Early start
